Workbook

Sheet CONCENTRADO
A1: CLAVE | B1: CONCEPTO | C1: SUBCLAVE | D1: CONCEPTO | E1: PRESUPUESTO | F1: ENERO | G1: FEBRERO | H1: MARZO | I1: ABRIL | J1: MAYO | K1: JUNIO | L1: JULIO | M1: AGOSTO | N1: SEPTIEMBRE | O1: OCTUBRE | P1: NOVIEMBRE | Q1: DICIEMBRE | R1: TOTAL ACUMULADO | S1: VARIACIÓN PRESUPUESTARÍA | T1: OBSERVACIONES
A2: MDE2025-001 | B2: DISEÑADORES BODEGA | C2: MDE2025-001 | D2: Diseñadores Bodega | F2: =IFERROR(SUMIF('ENE25'!E:E,CONCENTRADO!$C2,'ENE25'!F:F),"") -> 13900 | G2: =IFERROR(SUMIF('FEB25'!$E:$E,CONCENTRADO!$C2,'FEB25'!$F:$F),"") -> 25260.62 | H2: =IFERROR(SUMIF('MAR25'!$E:$E,CONCENTRADO!$C2,'MAR25'!$F:$F),"") -> 66007.76 | I2: =IFERROR(SUMIF('ABR25'!$E:$E,CONCENTRADO!$C2,'ABR25'!$F:$F),"") -> 42393.37 | J2: =IFERROR(SUMIF('MAY25'!$E:$E,CONCENTRADO!$C2,'MAY25'!$F:$F),"") -> 0 | K2: =IFERROR(SUMIF('JUN25'!$E:$E,CONCENTRADO!$C2,'JUN25'!$F:$F),"") -> 0 | L2: =IFERROR(SUMIF('JUL25'!$E:$E,CONCENTRADO!$C2,'JUL25'!$F:$F),"") -> 19500 | M2: =IFERROR(SUMIF('AGO25'!$E:$E,CONCENTRADO!$C2,'AGO25'!$F:$F),"") -> 0 | N2: =IFERROR(SUMIF('SEP25'!$E:$E,CONCENTRADO!$C2,'SEP25'!$F:$F),"") -> 206.03 | O2: =IFERROR(SUMIF('OCT25'!$E:$E,CONCENTRADO!$C2,'OCT25'!$F:$F),"") -> 1024.12 | P2: =IFERROR(SUMIF('NOV25'!$E:$E,CONCENTRADO!$C2,'NOV25'!$F:$F),"") -> 7256.03 | Q2: =IFERROR(SUMIF('DIC25'!$E:$E,CONCENTRADO!$C2,'DIC25'!$K:$K),"") -> 0 | R2: =SUM(K2:Q2) -> 27986.18 | S2: =$E2-$R2 -> -27986.18
A3: MDE2025-002 | B3: GASTOS FIJOS | C3: MDE2025-002A | D3: Servicio de recolección de basura y desechos industriales | F3: =IFERROR(SUMIF('ENE25'!E:E,CONCENTRADO!$C3,'ENE25'!F:F),"") -> 2650 | G3: =IFERROR(SUMIF('FEB25'!$E:$E,CONCENTRADO!$C3,'FEB25'!$F:$F),"") -> 2800 | H3: =IFERROR(SUMIF('MAR25'!$E:$E,CONCENTRADO!$C3,'MAR25'!$F:$F),"") -> 2800 | I3: =IFERROR(SUMIF('ABR25'!$E:$E,CONCENTRADO!$C3,'ABR25'!$F:$F),"") -> 2800 | J3: =IFERROR(SUMIF('MAY25'!$E:$E,CONCENTRADO!$C3,'MAY25'!$F:$F),"") -> 3500 | K3: =IFERROR(SUMIF('JUN25'!$E:$E,CONCENTRADO!$C3,'JUN25'!$F:$F),"") -> 2800 | L3: =IFERROR(SUMIF('JUL25'!$E:$E,CONCENTRADO!$C3,'JUL25'!$F:$F),"") -> 3500 | M3: =IFERROR(SUMIF('AGO25'!$E:$E,CONCENTRADO!$C3,'AGO25'!$F:$F),"") -> 2800 | N3: =IFERROR(SUMIF('SEP25'!$E:$E,CONCENTRADO!$C3,'SEP25'!$F:$F),"") -> 3000 | O3: =IFERROR(SUMIF('OCT25'!$E:$E,CONCENTRADO!$C3,'OCT25'!$F:$F),"") -> 3750 | P3: =IFERROR(SUMIF('NOV25'!$E:$E,CONCENTRADO!$C3,'NOV25'!$F:$F),"") -> 5300 | Q3: =IFERROR(SUMIF('DIC25'!$E:$E,CONCENTRADO!$C3,'DIC25'!$K:$K),"") -> 0 | R3: =SUM(K3:Q3) -> 21150 | S3: =$E3-$R3 -> -21150
C4: MDE2025-002B | D4: Agua embotellada | F4: =IFERROR(SUMIF('ENE25'!E:E,CONCENTRADO!$C4,'ENE25'!F:F),"") -> 475 | G4: =IFERROR(SUMIF('FEB25'!$E:$E,CONCENTRADO!$C4,'FEB25'!$F:$F),"") -> 473 | H4: =IFERROR(SUMIF('MAR25'!$E:$E,CONCENTRADO!$C4,'MAR25'!$F:$F),"") -> 1449 | I4: =IFERROR(SUMIF('ABR25'!$E:$E,CONCENTRADO!$C4,'ABR25'!$F:$F),"") -> 1590 | J4: =IFERROR(SUMIF('MAY25'!$E:$E,CONCENTRADO!$C4,'MAY25'!$F:$F),"") -> 1292 | K4: =IFERROR(SUMIF('JUN25'!$E:$E,CONCENTRADO!$C4,'JUN25'!$F:$F),"") -> 1400 | L4: =IFERROR(SUMIF('JUL25'!$E:$E,CONCENTRADO!$C4,'JUL25'!$F:$F),"") -> 1400 | M4: =IFERROR(SUMIF('AGO25'!$E:$E,CONCENTRADO!$C4,'AGO25'!$F:$F),"") -> 900 | N4: =IFERROR(SUMIF('SEP25'!$E:$E,CONCENTRADO!$C4,'SEP25'!$F:$F),"") -> 1550 | O4: =IFERROR(SUMIF('OCT25'!$E:$E,CONCENTRADO!$C4,'OCT25'!$F:$F),"") -> 1950 | P4: =IFERROR(SUMIF('NOV25'!$E:$E,CONCENTRADO!$C4,'NOV25'!$F:$F),"") -> 0 | Q4: =IFERROR(SUMIF('DIC25'!$E:$E,CONCENTRADO!$C4,'DIC25'!$K:$K),"") -> 0 | R4: =SUM(K4:Q4) -> 7200 | S4: =$E4-$R4 -> -7200
C5: MDE2025-002C | D5: Servicio de luz | F5: =IFERROR(SUMIF('ENE25'!E:E,CONCENTRADO!$C5,'ENE25'!F:F),"") -> 4903 | G5: =IFERROR(SUMIF('FEB25'!$E:$E,CONCENTRADO!$C5,'FEB25'!$F:$F),"") -> 7177 | H5: =IFERROR(SUMIF('MAR25'!$E:$E,CONCENTRADO!$C5,'MAR25'!$F:$F),"") -> 6994 | I5: =IFERROR(SUMIF('ABR25'!$E:$E,CONCENTRADO!$C5,'ABR25'!$F:$F),"") -> 8210 | J5: =IFERROR(SUMIF('MAY25'!$E:$E,CONCENTRADO!$C5,'MAY25'!$F:$F),"") -> 9753 | K5: =IFERROR(SUMIF('JUN25'!$E:$E,CONCENTRADO!$C5,'JUN25'!$F:$F),"") -> 10921 | L5: =IFERROR(SUMIF('JUL25'!$E:$E,CONCENTRADO!$C5,'JUL25'!$F:$F),"") -> 9165.52 | M5: =IFERROR(SUMIF('AGO25'!$E:$E,CONCENTRADO!$C5,'AGO25'!$F:$F),"") -> 0 | N5: =IFERROR(SUMIF('SEP25'!$E:$E,CONCENTRADO!$C5,'SEP25'!$F:$F),"") -> 0 | O5: =IFERROR(SUMIF('OCT25'!$E:$E,CONCENTRADO!$C5,'OCT25'!$F:$F),"") -> 1500 | P5: =IFERROR(SUMIF('NOV25'!$E:$E,CONCENTRADO!$C5,'NOV25'!$F:$F),"") -> 0 | Q5: =IFERROR(SUMIF('DIC25'!$E:$E,CONCENTRADO!$C5,'DIC25'!$K:$K),"") -> 0 | R5: =SUM(K5:Q5) -> 21586.52 | S5: =$E5-$R5 -> -21586.52
C6: MDE2025-002D | D6: Rentas | F6: =IFERROR(SUMIF('ENE25'!E:E,CONCENTRADO!$C6,'ENE25'!F:F),"") -> 167327.59 | G6: =IFERROR(SUMIF('FEB25'!$E:$E,CONCENTRADO!$C6,'FEB25'!$F:$F),"") -> 87327.59 | H6: =IFERROR(SUMIF('MAR25'!$E:$E,CONCENTRADO!$C6,'MAR25'!$F:$F),"") -> 87327.59 | I6: =IFERROR(SUMIF('ABR25'!$E:$E,CONCENTRADO!$C6,'ABR25'!$F:$F),"") -> 87327.59 | J6: =IFERROR(SUMIF('MAY25'!$E:$E,CONCENTRADO!$C6,'MAY25'!$F:$F),"") -> 20771.79 | K6: =IFERROR(SUMIF('JUN25'!$E:$E,CONCENTRADO!$C6,'JUN25'!$F:$F),"") -> 80000 | L6: =IFERROR(SUMIF('JUL25'!$E:$E,CONCENTRADO!$C6,'JUL25'!$F:$F),"") -> 80000 | M6: =IFERROR(SUMIF('AGO25'!$E:$E,CONCENTRADO!$C6,'AGO25'!$F:$F),"") -> 7327.59 | N6: =IFERROR(SUMIF('SEP25'!$E:$E,CONCENTRADO!$C6,'SEP25'!$F:$F),"") -> 7327.59 | O6: =IFERROR(SUMIF('OCT25'!$E:$E,CONCENTRADO!$C6,'OCT25'!$F:$F),"") -> 7327.59 | P6: =IFERROR(SUMIF('NOV25'!$E:$E,CONCENTRADO!$C6,'NOV25'!$F:$F),"") -> 7758.62 | Q6: =IFERROR(SUMIF('DIC25'!$E:$E,CONCENTRADO!$C6,'DIC25'!$K:$K),"") -> 0 | R6: =SUM(K6:Q6) -> 189741.39 | S6: =$E6-$R6 -> -189741.39
C7: MDE2025-002E | D7: Agua potable | F7: =IFERROR(SUMIF('ENE25'!E:E,CONCENTRADO!$C7,'ENE25'!F:F),"") -> 508.01 | G7: =IFERROR(SUMIF('FEB25'!$E:$E,CONCENTRADO!$C7,'FEB25'!$F:$F),"") -> 0 | H7: =IFERROR(SUMIF('MAR25'!$E:$E,CONCENTRADO!$C7,'MAR25'!$F:$F),"") -> 496 | I7: =IFERROR(SUMIF('ABR25'!$E:$E,CONCENTRADO!$C7,'ABR25'!$F:$F),"") -> 0 | J7: =IFERROR(SUMIF('MAY25'!$E:$E,CONCENTRADO!$C7,'MAY25'!$F:$F),"") -> 388.79 | K7: =IFERROR(SUMIF('JUN25'!$E:$E,CONCENTRADO!$C7,'JUN25'!$F:$F),"") -> 0 | L7: =IFERROR(SUMIF('JUL25'!$E:$E,CONCENTRADO!$C7,'JUL25'!$F:$F),"") -> 0 | M7: =IFERROR(SUMIF('AGO25'!$E:$E,CONCENTRADO!$C7,'AGO25'!$F:$F),"") -> 0 | N7: =IFERROR(SUMIF('SEP25'!$E:$E,CONCENTRADO!$C7,'SEP25'!$F:$F),"") -> 701 | O7: =IFERROR(SUMIF('OCT25'!$E:$E,CONCENTRADO!$C7,'OCT25'!$F:$F),"") -> 0 | P7: =IFERROR(SUMIF('NOV25'!$E:$E,CONCENTRADO!$C7,'NOV25'!$F:$F),"") -> 692 | Q7: =IFERROR(SUMIF('DIC25'!$E:$E,CONCENTRADO!$C7,'DIC25'!$K:$K),"") -> 0 | R7: =SUM(K7:Q7) -> 1393 | S7: =$E7-$R7 -> -1393
C8: MDE2025-002F | D8: Servicios telefónicos e internet | F8: =IFERROR(SUMIF('ENE25'!E:E,CONCENTRADO!$C8,'ENE25'!F:F),"") -> 22436 | G8: =IFERROR(SUMIF('FEB25'!$E:$E,CONCENTRADO!$C8,'FEB25'!$F:$F),"") -> 5791 | H8: =IFERROR(SUMIF('MAR25'!$E:$E,CONCENTRADO!$C8,'MAR25'!$F:$F),"") -> 5008.63 | I8: =IFERROR(SUMIF('ABR25'!$E:$E,CONCENTRADO!$C8,'ABR25'!$F:$F),"") -> 5570.58 | J8: =IFERROR(SUMIF('MAY25'!$E:$E,CONCENTRADO!$C8,'MAY25'!$F:$F),"") -> 5570.6 | K8: =IFERROR(SUMIF('JUN25'!$E:$E,CONCENTRADO!$C8,'JUN25'!$F:$F),"") -> 3111.38 | L8: =IFERROR(SUMIF('JUL25'!$E:$E,CONCENTRADO!$C8,'JUL25'!$F:$F),"") -> 8326 | M8: =IFERROR(SUMIF('AGO25'!$E:$E,CONCENTRADO!$C8,'AGO25'!$F:$F),"") -> 4299.62 | N8: =IFERROR(SUMIF('SEP25'!$E:$E,CONCENTRADO!$C8,'SEP25'!$F:$F),"") -> 12671 | O8: =IFERROR(SUMIF('OCT25'!$E:$E,CONCENTRADO!$C8,'OCT25'!$F:$F),"") -> 1878.8 | P8: =IFERROR(SUMIF('NOV25'!$E:$E,CONCENTRADO!$C8,'NOV25'!$F:$F),"") -> 7598 | Q8: =IFERROR(SUMIF('DIC25'!$E:$E,CONCENTRADO!$C8,'DIC25'!$K:$K),"") -> 0 | R8: =SUM(K8:Q8) -> 37884.8 | S8: =$E8-$R8 -> -37884.8
C9: MDE2025-002G | D9: Comisiones e intereses bancarios | F9: =IFERROR(SUMIF('ENE25'!E:E,CONCENTRADO!$C9,'ENE25'!F:F),"") -> 9389.01 | G9: =IFERROR(SUMIF('FEB25'!$E:$E,CONCENTRADO!$C9,'FEB25'!$F:$F),"") -> 0 | H9: =IFERROR(SUMIF('MAR25'!$E:$E,CONCENTRADO!$C9,'MAR25'!$F:$F),"") -> 0 | I9: =IFERROR(SUMIF('ABR25'!$E:$E,CONCENTRADO!$C9,'ABR25'!$F:$F),"") -> 0 | J9: =IFERROR(SUMIF('MAY25'!$E:$E,CONCENTRADO!$C9,'MAY25'!$F:$F),"") -> 520 | K9: =IFERROR(SUMIF('JUN25'!$E:$E,CONCENTRADO!$C9,'JUN25'!$F:$F),"") -> 520 | L9: =IFERROR(SUMIF('JUL25'!$E:$E,CONCENTRADO!$C9,'JUL25'!$F:$F),"") -> 520 | M9: =IFERROR(SUMIF('AGO25'!$E:$E,CONCENTRADO!$C9,'AGO25'!$F:$F),"") -> 0 | N9: =IFERROR(SUMIF('SEP25'!$E:$E,CONCENTRADO!$C9,'SEP25'!$F:$F),"") -> 4520 | O9: =IFERROR(SUMIF('OCT25'!$E:$E,CONCENTRADO!$C9,'OCT25'!$F:$F),"") -> 520 | P9: =IFERROR(SUMIF('NOV25'!$E:$E,CONCENTRADO!$C9,'NOV25'!$F:$F),"") -> 520 | Q9: =IFERROR(SUMIF('DIC25'!$E:$E,CONCENTRADO!$C9,'DIC25'!$K:$K),"") -> 0 | R9: =SUM(K9:Q9) -> 6600 | S9: =$E9-$R9 -> -6600
C10: MDE2025-002H | D10: Impuesto predial | F10: =IFERROR(SUMIF('ENE25'!E:E,CONCENTRADO!$C10,'ENE25'!F:F),"") -> 0 | G10: =IFERROR(SUMIF('FEB25'!$E:$E,CONCENTRADO!$C10,'FEB25'!$F:$F),"") -> 0 | H10: =IFERROR(SUMIF('MAR25'!$E:$E,CONCENTRADO!$C10,'MAR25'!$F:$F),"") -> 0 | I10: =IFERROR(SUMIF('ABR25'!$E:$E,CONCENTRADO!$C10,'ABR25'!$F:$F),"") -> 0 | J10: =IFERROR(SUMIF('MAY25'!$E:$E,CONCENTRADO!$C10,'MAY25'!$F:$F),"") -> 0 | K10: =IFERROR(SUMIF('JUN25'!$E:$E,CONCENTRADO!$C10,'JUN25'!$F:$F),"") -> 0 | L10: =IFERROR(SUMIF('JUL25'!$E:$E,CONCENTRADO!$C10,'JUL25'!$F:$F),"") -> 0 | M10: =IFERROR(SUMIF('AGO25'!$E:$E,CONCENTRADO!$C10,'AGO25'!$F:$F),"") -> 0 | N10: =IFERROR(SUMIF('SEP25'!$E:$E,CONCENTRADO!$C10,'SEP25'!$F:$F),"") -> 0 | O10: =IFERROR(SUMIF('OCT25'!$E:$E,CONCENTRADO!$C10,'OCT25'!$F:$F),"") -> 0 | P10: =IFERROR(SUMIF('NOV25'!$E:$E,CONCENTRADO!$C10,'NOV25'!$F:$F),"") -> 0 | Q10: =IFERROR(SUMIF('DIC25'!$E:$E,CONCENTRADO!$C10,'DIC25'!$K:$K),"") -> 0 | R10: =SUM(K10:Q10) -> 0 | S10: =$E10-$R10 -> 0
C11: MDE2025-002I | D11: Social media y web master | F11: =IFERROR(SUMIF('ENE25'!E:E,CONCENTRADO!$C11,'ENE25'!F:F),"") -> 8000 | G11: =IFERROR(SUMIF('FEB25'!$E:$E,CONCENTRADO!$C11,'FEB25'!$F:$F),"") -> 8000 | H11: =IFERROR(SUMIF('MAR25'!$E:$E,CONCENTRADO!$C11,'MAR25'!$F:$F),"") -> 8000 | I11: =IFERROR(SUMIF('ABR25'!$E:$E,CONCENTRADO!$C11,'ABR25'!$F:$F),"") -> 8000 | J11: =IFERROR(SUMIF('MAY25'!$E:$E,CONCENTRADO!$C11,'MAY25'!$F:$F),"") -> 8000 | K11: =IFERROR(SUMIF('JUN25'!$E:$E,CONCENTRADO!$C11,'JUN25'!$F:$F),"") -> 8000 | L11: =IFERROR(SUMIF('JUL25'!$E:$E,CONCENTRADO!$C11,'JUL25'!$F:$F),"") -> 8000 | M11: =IFERROR(SUMIF('AGO25'!$E:$E,CONCENTRADO!$C11,'AGO25'!$F:$F),"") -> 8599 | N11: =IFERROR(SUMIF('SEP25'!$E:$E,CONCENTRADO!$C11,'SEP25'!$F:$F),"") -> 8000 | O11: =IFERROR(SUMIF('OCT25'!$E:$E,CONCENTRADO!$C11,'OCT25'!$F:$F),"") -> 8000 | P11: =IFERROR(SUMIF('NOV25'!$E:$E,CONCENTRADO!$C11,'NOV25'!$F:$F),"") -> 8000 | Q11: =IFERROR(SUMIF('DIC25'!$E:$E,CONCENTRADO!$C11,'DIC25'!$K:$K),"") -> 0 | R11: =SUM(K11:Q11) -> 48599 | S11: =$E11-$R11 -> -48599
C12: MDE2025-002J | D12: Licencias y certificaciones | F12: =IFERROR(SUMIF('ENE25'!E:E,CONCENTRADO!$C12,'ENE25'!F:F),"") -> 615.63 | G12: =IFERROR(SUMIF('FEB25'!$E:$E,CONCENTRADO!$C12,'FEB25'!$F:$F),"") -> 615.63 | H12: =IFERROR(SUMIF('MAR25'!$E:$E,CONCENTRADO!$C12,'MAR25'!$F:$F),"") -> 610.78 | I12: =IFERROR(SUMIF('ABR25'!$E:$E,CONCENTRADO!$C12,'ABR25'!$F:$F),"") -> 594.78 | J12: =IFERROR(SUMIF('MAY25'!$E:$E,CONCENTRADO!$C12,'MAY25'!$F:$F),"") -> 5646.12 | K12: =IFERROR(SUMIF('JUN25'!$E:$E,CONCENTRADO!$C12,'JUN25'!$F:$F),"") -> 130956.64 | L12: =IFERROR(SUMIF('JUL25'!$E:$E,CONCENTRADO!$C12,'JUL25'!$F:$F),"") -> 20794.9 | M12: =IFERROR(SUMIF('AGO25'!$E:$E,CONCENTRADO!$C12,'AGO25'!$F:$F),"") -> 10966.18 | N12: =IFERROR(SUMIF('SEP25'!$E:$E,CONCENTRADO!$C12,'SEP25'!$F:$F),"") -> 34466.22 | O12: =IFERROR(SUMIF('OCT25'!$E:$E,CONCENTRADO!$C12,'OCT25'!$F:$F),"") -> 3280.77 | P12: =IFERROR(SUMIF('NOV25'!$E:$E,CONCENTRADO!$C12,'NOV25'!$F:$F),"") -> 987.47 | Q12: =IFERROR(SUMIF('DIC25'!$E:$E,CONCENTRADO!$C12,'DIC25'!$K:$K),"") -> 0 | R12: =SUM(K12:Q12) -> 201452.18 | S12: =$E12-$R12 -> -201452.18
C13: MDE2025-002K | D13: Vigilancia | F13: =IFERROR(SUMIF('ENE25'!E:E,CONCENTRADO!$C13,'ENE25'!F:F),"") -> 31050 | G13: =IFERROR(SUMIF('FEB25'!$E:$E,CONCENTRADO!$C13,'FEB25'!$F:$F),"") -> 31050 | H13: =IFERROR(SUMIF('MAR25'!$E:$E,CONCENTRADO!$C13,'MAR25'!$F:$F),"") -> 31050 | I13: =IFERROR(SUMIF('ABR25'!$E:$E,CONCENTRADO!$C13,'ABR25'!$F:$F),"") -> 31050 | J13: =IFERROR(SUMIF('MAY25'!$E:$E,CONCENTRADO!$C13,'MAY25'!$F:$F),"") -> 31199 | K13: =IFERROR(SUMIF('JUN25'!$E:$E,CONCENTRADO!$C13,'JUN25'!$F:$F),"") -> 15525 | L13: =IFERROR(SUMIF('JUL25'!$E:$E,CONCENTRADO!$C13,'JUL25'!$F:$F),"") -> 31050 | M13: =IFERROR(SUMIF('AGO25'!$E:$E,CONCENTRADO!$C13,'AGO25'!$F:$F),"") -> 31050 | N13: =IFERROR(SUMIF('SEP25'!$E:$E,CONCENTRADO!$C13,'SEP25'!$F:$F),"") -> 31050 | O13: =IFERROR(SUMIF('OCT25'!$E:$E,CONCENTRADO!$C13,'OCT25'!$F:$F),"") -> 34000 | P13: =IFERROR(SUMIF('NOV25'!$E:$E,CONCENTRADO!$C13,'NOV25'!$F:$F),"") -> 0 | Q13: =IFERROR(SUMIF('DIC25'!$E:$E,CONCENTRADO!$C13,'DIC25'!$K:$K),"") -> 0 | R13: =SUM(K13:Q13) -> 142675 | S13: =$E13-$R13 -> -142675
C14: MDE2025-002L | D14: Nómina semanal bodega | F14: =IFERROR(SUMIF('ENE25'!E:E,CONCENTRADO!$C14,'ENE25'!F:F),"") -> 516623.06 | G14: =IFERROR(SUMIF('FEB25'!$E:$E,CONCENTRADO!$C14,'FEB25'!$F:$F),"") -> 112188.63 | H14: =IFERROR(SUMIF('MAR25'!$E:$E,CONCENTRADO!$C14,'MAR25'!$F:$F),"") -> 133921.07 | I14: =IFERROR(SUMIF('ABR25'!$E:$E,CONCENTRADO!$C14,'ABR25'!$F:$F),"") -> 342431.74 | J14: =IFERROR(SUMIF('MAY25'!$E:$E,CONCENTRADO!$C14,'MAY25'!$F:$F),"") -> 101410.63 | K14: =IFERROR(SUMIF('JUN25'!$E:$E,CONCENTRADO!$C14,'JUN25'!$F:$F),"") -> 117811.71 | L14: =IFERROR(SUMIF('JUL25'!$E:$E,CONCENTRADO!$C14,'JUL25'!$F:$F),"") -> 121900.52 | M14: =IFERROR(SUMIF('AGO25'!$E:$E,CONCENTRADO!$C14,'AGO25'!$F:$F),"") -> 114562.92 | N14: =IFERROR(SUMIF('SEP25'!$E:$E,CONCENTRADO!$C14,'SEP25'!$F:$F),"") -> 132689.33 | O14: =IFERROR(SUMIF('OCT25'!$E:$E,CONCENTRADO!$C14,'OCT25'!$F:$F),"") -> 3920 | P14: =IFERROR(SUMIF('NOV25'!$E:$E,CONCENTRADO!$C14,'NOV25'!$F:$F),"") -> 0 | Q14: =IFERROR(SUMIF('DIC25'!$E:$E,CONCENTRADO!$C14,'DIC25'!$K:$K),"") -> 0 | R14: =SUM(K14:Q14) -> 490884.48 | S14: =$E14-$R14 -> -490884.48
C15: MDE2025-002M | D15: Carga social de nómina semanal | F15: =IFERROR(SUMIF('ENE25'!E:E,CONCENTRADO!$C15,'ENE25'!F:F),"") -> 0 | G15: =IFERROR(SUMIF('FEB25'!$E:$E,CONCENTRADO!$C15,'FEB25'!$F:$F),"") -> 0 | H15: =IFERROR(SUMIF('MAR25'!$E:$E,CONCENTRADO!$C15,'MAR25'!$F:$F),"") -> 0 | I15: =IFERROR(SUMIF('ABR25'!$E:$E,CONCENTRADO!$C15,'ABR25'!$F:$F),"") -> 0 | J15: =IFERROR(SUMIF('MAY25'!$E:$E,CONCENTRADO!$C15,'MAY25'!$F:$F),"") -> 0 | K15: =IFERROR(SUMIF('JUN25'!$E:$E,CONCENTRADO!$C15,'JUN25'!$F:$F),"") -> 0 | L15: =IFERROR(SUMIF('JUL25'!$E:$E,CONCENTRADO!$C15,'JUL25'!$F:$F),"") -> 0 | M15: =IFERROR(SUMIF('AGO25'!$E:$E,CONCENTRADO!$C15,'AGO25'!$F:$F),"") -> 0 | N15: =IFERROR(SUMIF('SEP25'!$E:$E,CONCENTRADO!$C15,'SEP25'!$F:$F),"") -> 0 | O15: =IFERROR(SUMIF('OCT25'!$E:$E,CONCENTRADO!$C15,'OCT25'!$F:$F),"") -> 0 | P15: =IFERROR(SUMIF('NOV25'!$E:$E,CONCENTRADO!$C15,'NOV25'!$F:$F),"") -> 0 | Q15: =IFERROR(SUMIF('DIC25'!$E:$E,CONCENTRADO!$C15,'DIC25'!$K:$K),"") -> 0 | R15: =SUM(K15:Q15) -> 0 | S15: =$E15-$R15 -> 0
... C20: MDE2025-002R | D20: Nómina en efectivo | F20: =IFERROR(SUMIF('ENE25'!E:E,CONCENTRADO!$C20,'ENE25'!F:F),"") -> 0 | G20: =IFERROR(SUMIF('FEB25'!$E:$E,CONCENTRADO!$C20,'FEB25'!$F:$F),"") -> 100000 | H20: =IFERROR(SUMIF('MAR25'!$E:$E,CONCENTRADO!$C20,'MAR25'!$F:$F),"") -> 0 | I20: =IFERROR(SUMIF('ABR25'!$E:$E,CONCENTRADO!$C20,'ABR25'!$F:$F),"") -> 0 | J20: =IFERROR(SUMIF('MAY25'!$E:$E,CONCENTRADO!$C20,'MAY25'!$F:$F),"") -> 300000 | K20: =IFERROR(SUMIF('JUN25'!$E:$E,CONCENTRADO!$C20,'JUN25'!$F:$F),"") -> 300000 | L20: =IFERROR(SUMIF('JUL25'!$E:$E,CONCENTRADO!$C20,'JUL25'!$F:$F),"") -> 0 | M20: =IFERROR(SUMIF('AGO25'!$E:$E,CONCENTRADO!$C20,'AGO25'!$F:$F),"") -> 0 | N20: =IFERROR(SUMIF('SEP25'!$E:$E,CONCENTRADO!$C20,'SEP25'!$F:$F),"") -> 352112.68 | O20: =IFERROR(SUMIF('OCT25'!$E:$E,CONCENTRADO!$C20,'OCT25'!$F:$F),"") -> 0 | P20: =IFERROR(SUMIF('NOV25'!$E:$E,CONCENTRADO!$C20,'NOV25'!$F:$F),"") -> 250000 | Q20: =IFERROR(SUMIF('DIC25'!$E:$E,CONCENTRADO!$C20,'DIC25'!$K:$K),"") -> 0 | R20: =SUM(K20:Q20) -> 902112.68 | S20: =$E20-$R20 -> -902112.68
F21: =IFERROR(SUMIF('ENE25'!E:E,CONCENTRADO!$C21,'ENE25'!F:F),"") -> 0 | G21: =IFERROR(SUMIF('FEB25'!$E:$E,CONCENTRADO!$C21,'FEB25'!$F:$F),"") -> 0 | H21: =IFERROR(SUMIF('MAR25'!$E:$E,CONCENTRADO!$C21,'MAR25'!$F:$F),"") -> 0 | I21: =IFERROR(SUMIF('ABR25'!$E:$E,CONCENTRADO!$C21,'ABR25'!$F:$F),"") -> 0 | J21: =IFERROR(SUMIF('MAY25'!$E:$E,CONCENTRADO!$C21,'MAY25'!$F:$F),"") -> 0 | K21: =IFERROR(SUMIF('JUN25'!$E:$E,CONCENTRADO!$C21,'JUN25'!$F:$F),"") -> 0 | L21: =IFERROR(SUMIF('JUL25'!$E:$E,CONCENTRADO!$C21,'JUL25'!$F:$F),"") -> 0 | M21: =IFERROR(SUMIF('AGO25'!$E:$E,CONCENTRADO!$C21,'AGO25'!$F:$F),"") -> 0 | N21: =IFERROR(SUMIF('SEP25'!$E:$E,CONCENTRADO!$C21,'SEP25'!$F:$F),"") -> 0 | O21: =IFERROR(SUMIF('OCT25'!$E:$E,CONCENTRADO!$C21,'OCT25'!$F:$F),"") -> 0 | P21: =IFERROR(SUMIF('NOV25'!$E:$E,CONCENTRADO!$C21,'NOV25'!$F:$F),"") -> 0 | Q21: =IFERROR(SUMIF('DIC25'!$E:$E,CONCENTRADO!$C21,'DIC25'!$K:$K),"") -> 0 | R21: =SUM(K21:Q21) -> 0 | S21: =$E21-$R21 -> 0
F22: =IFERROR(SUMIF('ENE25'!E:E,CONCENTRADO!$C22,'ENE25'!F:F),"") -> 0 | G22: =IFERROR(SUMIF('FEB25'!$E:$E,CONCENTRADO!$C22,'FEB25'!$F:$F),"") -> 0 | H22: =IFERROR(SUMIF('MAR25'!$E:$E,CONCENTRADO!$C22,'MAR25'!$F:$F),"") -> 0 | I22: =IFERROR(SUMIF('ABR25'!$E:$E,CONCENTRADO!$C22,'ABR25'!$F:$F),"") -> 0 | J22: =IFERROR(SUMIF('MAY25'!$E:$E,CONCENTRADO!$C22,'MAY25'!$F:$F),"") -> 0 | K22: =IFERROR(SUMIF('JUN25'!$E:$E,CONCENTRADO!$C22,'JUN25'!$F:$F),"") -> 0 | L22: =IFERROR(SUMIF('JUL25'!$E:$E,CONCENTRADO!$C22,'JUL25'!$F:$F),"") -> 0 | M22: =IFERROR(SUMIF('AGO25'!$E:$E,CONCENTRADO!$C22,'AGO25'!$F:$F),"") -> 0 | N22: =IFERROR(SUMIF('SEP25'!$E:$E,CONCENTRADO!$C22,'SEP25'!$F:$F),"") -> 0 | O22: =IFERROR(SUMIF('OCT25'!$E:$E,CONCENTRADO!$C22,'OCT25'!$F:$F),"") -> 0 | P22: =IFERROR(SUMIF('NOV25'!$E:$E,CONCENTRADO!$C22,'NOV25'!$F:$F),"") -> 0 | Q22: =IFERROR(SUMIF('DIC25'!$E:$E,CONCENTRADO!$C22,'DIC25'!$K:$K),"") -> 0 | R22: =SUM(K22:Q22) -> 0 | S22: =$E22-$R22 -> 0
F23: =IFERROR(SUMIF('ENE25'!E:E,CONCENTRADO!$C23,'ENE25'!F:F),"") -> 0 | G23: =IFERROR(SUMIF('FEB25'!$E:$E,CONCENTRADO!$C23,'FEB25'!$F:$F),"") -> 0 | H23: =IFERROR(SUMIF('MAR25'!$E:$E,CONCENTRADO!$C23,'MAR25'!$F:$F),"") -> 0 | I23: =IFERROR(SUMIF('ABR25'!$E:$E,CONCENTRADO!$C23,'ABR25'!$F:$F),"") -> 0 | J23: =IFERROR(SUMIF('MAY25'!$E:$E,CONCENTRADO!$C23,'MAY25'!$F:$F),"") -> 0 | K23: =IFERROR(SUMIF('JUN25'!$E:$E,CONCENTRADO!$C23,'JUN25'!$F:$F),"") -> 0 | L23: =IFERROR(SUMIF('JUL25'!$E:$E,CONCENTRADO!$C23,'JUL25'!$F:$F),"") -> 0 | M23: =IFERROR(SUMIF('AGO25'!$E:$E,CONCENTRADO!$C23,'AGO25'!$F:$F),"") -> 0 | N23: =IFERROR(SUMIF('SEP25'!$E:$E,CONCENTRADO!$C23,'SEP25'!$F:$F),"") -> 0 | O23: =IFERROR(SUMIF('OCT25'!$E:$E,CONCENTRADO!$C23,'OCT25'!$F:$F),"") -> 0 | P23: =IFERROR(SUMIF('NOV25'!$E:$E,CONCENTRADO!$C23,'NOV25'!$F:$F),"") -> 0 | Q23: =IFERROR(SUMIF('DIC25'!$E:$E,CONCENTRADO!$C23,'DIC25'!$K:$K),"") -> 0 | R23: =SUM(K23:Q23) -> 0 | S23: =$E23-$R23 -> 0
A24: MDE 2025-003 | B24: GASTOS VARIOS | C24: MDE2025-003A | D24: Papelería e insumos de limpieza | F24: =IFERROR(SUMIF('ENE25'!E:E,CONCENTRADO!$C24,'ENE25'!F:F),"") -> 50 | G24: =IFERROR(SUMIF('FEB25'!$E:$E,CONCENTRADO!$C24,'FEB25'!$F:$F),"") -> 6595.88 | H24: =IFERROR(SUMIF('MAR25'!$E:$E,CONCENTRADO!$C24,'MAR25'!$F:$F),"") -> 90 | I24: =IFERROR(SUMIF('ABR25'!$E:$E,CONCENTRADO!$C24,'ABR25'!$F:$F),"") -> 3052.66 | J24: =IFERROR(SUMIF('MAY25'!$E:$E,CONCENTRADO!$C24,'MAY25'!$F:$F),"") -> 5575.18 | K24: =IFERROR(SUMIF('JUN25'!$E:$E,CONCENTRADO!$C24,'JUN25'!$F:$F),"") -> 2141.31 | L24: =IFERROR(SUMIF('JUL25'!$E:$E,CONCENTRADO!$C24,'JUL25'!$F:$F),"") -> 11074.64 | M24: =IFERROR(SUMIF('AGO25'!$E:$E,CONCENTRADO!$C24,'AGO25'!$F:$F),"") -> 1363.03 | N24: =IFERROR(SUMIF('SEP25'!$E:$E,CONCENTRADO!$C24,'SEP25'!$F:$F),"") -> 4684.09 | O24: =IFERROR(SUMIF('OCT25'!$E:$E,CONCENTRADO!$C24,'OCT25'!$F:$F),"") -> 8284.5 | P24: =IFERROR(SUMIF('NOV25'!$E:$E,CONCENTRADO!$C24,'NOV25'!$F:$F),"") -> 10995.36 | Q24: =IFERROR(SUMIF('DIC25'!$E:$E,CONCENTRADO!$C24,'DIC25'!$K:$K),"") -> 0 | R24: =SUM(K24:Q24) -> 38542.93 | S24: =$E24-$R24 -> -38542.93
C25: MDE2025-003B | D25: Uniformes y EPP | F25: =IFERROR(SUMIF('ENE25'!E:E,CONCENTRADO!$C25,'ENE25'!F:F),"") -> 128 | G25: =IFERROR(SUMIF('FEB25'!$E:$E,CONCENTRADO!$C25,'FEB25'!$F:$F),"") -> 3175.49 | H25: =IFERROR(SUMIF('MAR25'!$E:$E,CONCENTRADO!$C25,'MAR25'!$F:$F),"") -> 1537.1 | I25: =IFERROR(SUMIF('ABR25'!$E:$E,CONCENTRADO!$C25,'ABR25'!$F:$F),"") -> 0 | J25: =IFERROR(SUMIF('MAY25'!$E:$E,CONCENTRADO!$C25,'MAY25'!$F:$F),"") -> 0 | K25: =IFERROR(SUMIF('JUN25'!$E:$E,CONCENTRADO!$C25,'JUN25'!$F:$F),"") -> 9897 | L25: =IFERROR(SUMIF('JUL25'!$E:$E,CONCENTRADO!$C25,'JUL25'!$F:$F),"") -> 4618.98 | M25: =IFERROR(SUMIF('AGO25'!$E:$E,CONCENTRADO!$C25,'AGO25'!$F:$F),"") -> 1189.65 | N25: =IFERROR(SUMIF('SEP25'!$E:$E,CONCENTRADO!$C25,'SEP25'!$F:$F),"") -> 111.2 | O25: =IFERROR(SUMIF('OCT25'!$E:$E,CONCENTRADO!$C25,'OCT25'!$F:$F),"") -> 0 | P25: =IFERROR(SUMIF('NOV25'!$E:$E,CONCENTRADO!$C25,'NOV25'!$F:$F),"") -> 10073 | Q25: =IFERROR(SUMIF('DIC25'!$E:$E,CONCENTRADO!$C25,'DIC25'!$K:$K),"") -> 0 | R25: =SUM(K25:Q25) -> 25889.83 | S25: =$E25-$R25 -> -25889.83
C26: MDE2025-003C | D26: Telefonía e internet | F26: =IFERROR(SUMIF('ENE25'!E:E,CONCENTRADO!$C26,'ENE25'!F:F),"") -> 1684.21 | G26: =IFERROR(SUMIF('FEB25'!$E:$E,CONCENTRADO!$C26,'FEB25'!$F:$F),"") -> 100 | H26: =IFERROR(SUMIF('MAR25'!$E:$E,CONCENTRADO!$C26,'MAR25'!$F:$F),"") -> 0 | I26: =IFERROR(SUMIF('ABR25'!$E:$E,CONCENTRADO!$C26,'ABR25'!$F:$F),"") -> 0 | J26: =IFERROR(SUMIF('MAY25'!$E:$E,CONCENTRADO!$C26,'MAY25'!$F:$F),"") -> 100 | K26: =IFERROR(SUMIF('JUN25'!$E:$E,CONCENTRADO!$C26,'JUN25'!$F:$F),"") -> 0 | L26: =IFERROR(SUMIF('JUL25'!$E:$E,CONCENTRADO!$C26,'JUL25'!$F:$F),"") -> 0 | M26: =IFERROR(SUMIF('AGO25'!$E:$E,CONCENTRADO!$C26,'AGO25'!$F:$F),"") -> 0 | N26: =IFERROR(SUMIF('SEP25'!$E:$E,CONCENTRADO!$C26,'SEP25'!$F:$F),"") -> 0 | O26: =IFERROR(SUMIF('OCT25'!$E:$E,CONCENTRADO!$C26,'OCT25'!$F:$F),"") -> 0 | P26: =IFERROR(SUMIF('NOV25'!$E:$E,CONCENTRADO!$C26,'NOV25'!$F:$F),"") -> 0 | Q26: =IFERROR(SUMIF('DIC25'!$E:$E,CONCENTRADO!$C26,'DIC25'!$K:$K),"") -> 0 | R26: =SUM(K26:Q26) -> 0 | S26: =$E26-$R26 -> 0
C27: MDE2025-003D | D27: Combustibles | F27: =IFERROR(SUMIF('ENE25'!E:E,CONCENTRADO!$C27,'ENE25'!F:F),"") -> 3231.5 | G27: =IFERROR(SUMIF('FEB25'!$E:$E,CONCENTRADO!$C27,'FEB25'!$F:$F),"") -> 1283.39 | H27: =IFERROR(SUMIF('MAR25'!$E:$E,CONCENTRADO!$C27,'MAR25'!$F:$F),"") -> 4432.08 | I27: =IFERROR(SUMIF('ABR25'!$E:$E,CONCENTRADO!$C27,'ABR25'!$F:$F),"") -> 2131.41 | J27: =IFERROR(SUMIF('MAY25'!$E:$E,CONCENTRADO!$C27,'MAY25'!$F:$F),"") -> 2711.62 | K27: =IFERROR(SUMIF('JUN25'!$E:$E,CONCENTRADO!$C27,'JUN25'!$F:$F),"") -> 819.22 | L27: =IFERROR(SUMIF('JUL25'!$E:$E,CONCENTRADO!$C27,'JUL25'!$F:$F),"") -> 5090.01 | M27: =IFERROR(SUMIF('AGO25'!$E:$E,CONCENTRADO!$C27,'AGO25'!$F:$F),"") -> 2899.81 | N27: =IFERROR(SUMIF('SEP25'!$E:$E,CONCENTRADO!$C27,'SEP25'!$F:$F),"") -> 5780.66 | O27: =IFERROR(SUMIF('OCT25'!$E:$E,CONCENTRADO!$C27,'OCT25'!$F:$F),"") -> 3284.13 | P27: =IFERROR(SUMIF('NOV25'!$E:$E,CONCENTRADO!$C27,'NOV25'!$F:$F),"") -> 288.44 | Q27: =IFERROR(SUMIF('DIC25'!$E:$E,CONCENTRADO!$C27,'DIC25'!$K:$K),"") -> 0 | R27: =SUM(K27:Q27) -> 18162.27 | S27: =$E27-$R27 -> -18162.27
C28: MDE2025-003F | D28: Farmacia/salud | F28: =IFERROR(SUMIF('ENE25'!E:E,CONCENTRADO!$C28,'ENE25'!F:F),"") -> 0 | G28: =IFERROR(SUMIF('FEB25'!$E:$E,CONCENTRADO!$C28,'FEB25'!$F:$F),"") -> 0 | H28: =IFERROR(SUMIF('MAR25'!$E:$E,CONCENTRADO!$C28,'MAR25'!$F:$F),"") -> 0 | I28: =IFERROR(SUMIF('ABR25'!$E:$E,CONCENTRADO!$C28,'ABR25'!$F:$F),"") -> 0 | J28: =IFERROR(SUMIF('MAY25'!$E:$E,CONCENTRADO!$C28,'MAY25'!$F:$F),"") -> 0 | K28: =IFERROR(SUMIF('JUN25'!$E:$E,CONCENTRADO!$C28,'JUN25'!$F:$F),"") -> 0 | L28: =IFERROR(SUMIF('JUL25'!$E:$E,CONCENTRADO!$C28,'JUL25'!$F:$F),"") -> 1052.69 | M28: =IFERROR(SUMIF('AGO25'!$E:$E,CONCENTRADO!$C28,'AGO25'!$F:$F),"") -> 566.01 | N28: =IFERROR(SUMIF('SEP25'!$E:$E,CONCENTRADO!$C28,'SEP25'!$F:$F),"") -> 55 | O28: =IFERROR(SUMIF('OCT25'!$E:$E,CONCENTRADO!$C28,'OCT25'!$F:$F),"") -> 0 | P28: =IFERROR(SUMIF('NOV25'!$E:$E,CONCENTRADO!$C28,'NOV25'!$F:$F),"") -> 230.5 | Q28: =IFERROR(SUMIF('DIC25'!$E:$E,CONCENTRADO!$C28,'DIC25'!$K:$K),"") -> 0 | R28: =SUM(K28:Q28) -> 1904.2 | S28: =$E28-$R28 -> -1904.2
C29: MDE2025-003H | D29: Alimentos y consumos | F29: =IFERROR(SUMIF('ENE25'!E:E,CONCENTRADO!$C29,'ENE25'!F:F),"") -> 279 | G29: =IFERROR(SUMIF('FEB25'!$E:$E,CONCENTRADO!$C29,'FEB25'!$F:$F),"") -> 0 | H29: =IFERROR(SUMIF('MAR25'!$E:$E,CONCENTRADO!$C29,'MAR25'!$F:$F),"") -> 0 | I29: =IFERROR(SUMIF('ABR25'!$E:$E,CONCENTRADO!$C29,'ABR25'!$F:$F),"") -> 0 | J29: =IFERROR(SUMIF('MAY25'!$E:$E,CONCENTRADO!$C29,'MAY25'!$F:$F),"") -> 1612.93 | K29: =IFERROR(SUMIF('JUN25'!$E:$E,CONCENTRADO!$C29,'JUN25'!$F:$F),"") -> 16228.96 | L29: =IFERROR(SUMIF('JUL25'!$E:$E,CONCENTRADO!$C29,'JUL25'!$F:$F),"") -> 0 | M29: =IFERROR(SUMIF('AGO25'!$E:$E,CONCENTRADO!$C29,'AGO25'!$F:$F),"") -> 0 | N29: =IFERROR(SUMIF('SEP25'!$E:$E,CONCENTRADO!$C29,'SEP25'!$F:$F),"") -> 0 | O29: =IFERROR(SUMIF('OCT25'!$E:$E,CONCENTRADO!$C29,'OCT25'!$F:$F),"") -> 0 | P29: =IFERROR(SUMIF('NOV25'!$E:$E,CONCENTRADO!$C29,'NOV25'!$F:$F),"") -> 0 | Q29: =IFERROR(SUMIF('DIC25'!$E:$E,CONCENTRADO!$C29,'DIC25'!$K:$K),"") -> 0 | R29: =SUM(K29:Q29) -> 16228.96 | S29: =$E29-$R29 -> -16228.96
C30: MDE2025-003I | D30: Hospedaje staff | F30: =IFERROR(SUMIF('ENE25'!E:E,CONCENTRADO!$C30,'ENE25'!F:F),"") -> 0 | G30: =IFERROR(SUMIF('FEB25'!$E:$E,CONCENTRADO!$C30,'FEB25'!$F:$F),"") -> 0 | H30: =IFERROR(SUMIF('MAR25'!$E:$E,CONCENTRADO!$C30,'MAR25'!$F:$F),"") -> 0 | I30: =IFERROR(SUMIF('ABR25'!$E:$E,CONCENTRADO!$C30,'ABR25'!$F:$F),"") -> 0 | J30: =IFERROR(SUMIF('MAY25'!$E:$E,CONCENTRADO!$C30,'MAY25'!$F:$F),"") -> 0 | K30: =IFERROR(SUMIF('JUN25'!$E:$E,CONCENTRADO!$C30,'JUN25'!$F:$F),"") -> 0 | L30: =IFERROR(SUMIF('JUL25'!$E:$E,CONCENTRADO!$C30,'JUL25'!$F:$F),"") -> 0 | M30: =IFERROR(SUMIF('AGO25'!$E:$E,CONCENTRADO!$C30,'AGO25'!$F:$F),"") -> 0 | N30: =IFERROR(SUMIF('SEP25'!$E:$E,CONCENTRADO!$C30,'SEP25'!$F:$F),"") -> 0 | O30: =IFERROR(SUMIF('OCT25'!$E:$E,CONCENTRADO!$C30,'OCT25'!$F:$F),"") -> 0 | P30: =IFERROR(SUMIF('NOV25'!$E:$E,CONCENTRADO!$C30,'NOV25'!$F:$F),"") -> 0 | Q30: =IFERROR(SUMIF('DIC25'!$E:$E,CONCENTRADO!$C30,'DIC25'!$K:$K),"") -> 0 | R30: =SUM(K30:Q30) -> 0 | S30: =$E30-$R30 -> 0
C31: MDE2025-003J | D31: Vuelos staff | F31: =IFERROR(SUMIF('ENE25'!E:E,CONCENTRADO!$C31,'ENE25'!F:F),"") -> 0 | G31: =IFERROR(SUMIF('FEB25'!$E:$E,CONCENTRADO!$C31,'FEB25'!$F:$F),"") -> 0 | H31: =IFERROR(SUMIF('MAR25'!$E:$E,CONCENTRADO!$C31,'MAR25'!$F:$F),"") -> 0 | I31: =IFERROR(SUMIF('ABR25'!$E:$E,CONCENTRADO!$C31,'ABR25'!$F:$F),"") -> 0 | J31: =IFERROR(SUMIF('MAY25'!$E:$E,CONCENTRADO!$C31,'MAY25'!$F:$F),"") -> 0 | K31: =IFERROR(SUMIF('JUN25'!$E:$E,CONCENTRADO!$C31,'JUN25'!$F:$F),"") -> 0 | L31: =IFERROR(SUMIF('JUL25'!$E:$E,CONCENTRADO!$C31,'JUL25'!$F:$F),"") -> 0 | M31: =IFERROR(SUMIF('AGO25'!$E:$E,CONCENTRADO!$C31,'AGO25'!$F:$F),"") -> 0 | N31: =IFERROR(SUMIF('SEP25'!$E:$E,CONCENTRADO!$C31,'SEP25'!$F:$F),"") -> 0 | O31: =IFERROR(SUMIF('OCT25'!$E:$E,CONCENTRADO!$C31,'OCT25'!$F:$F),"") -> 0 | P31: =IFERROR(SUMIF('NOV25'!$E:$E,CONCENTRADO!$C31,'NOV25'!$F:$F),"") -> 0 | Q31: =IFERROR(SUMIF('DIC25'!$E:$E,CONCENTRADO!$C31,'DIC25'!$K:$K),"") -> 0 | R31: =SUM(K31:Q31) -> 0 | S31: =$E31-$R31 -> 0
C32: MDE2025-003K | D32: Proyectos futuros | F32: =IFERROR(SUMIF('ENE25'!E:E,CONCENTRADO!$C32,'ENE25'!F:F),"") -> 73260.46 | G32: =IFERROR(SUMIF('FEB25'!$E:$E,CONCENTRADO!$C32,'FEB25'!$F:$F),"") -> 42000 | H32: =IFERROR(SUMIF('MAR25'!$E:$E,CONCENTRADO!$C32,'MAR25'!$F:$F),"") -> 0 | I32: =IFERROR(SUMIF('ABR25'!$E:$E,CONCENTRADO!$C32,'ABR25'!$F:$F),"") -> 400000 | J32: =IFERROR(SUMIF('MAY25'!$E:$E,CONCENTRADO!$C32,'MAY25'!$F:$F),"") -> 0 | K32: =IFERROR(SUMIF('JUN25'!$E:$E,CONCENTRADO!$C32,'JUN25'!$F:$F),"") -> 0 | L32: =IFERROR(SUMIF('JUL25'!$E:$E,CONCENTRADO!$C32,'JUL25'!$F:$F),"") -> 0 | M32: =IFERROR(SUMIF('AGO25'!$E:$E,CONCENTRADO!$C32,'AGO25'!$F:$F),"") -> 0 | N32: =IFERROR(SUMIF('SEP25'!$E:$E,CONCENTRADO!$C32,'SEP25'!$F:$F),"") -> 0 | O32: =IFERROR(SUMIF('OCT25'!$E:$E,CONCENTRADO!$C32,'OCT25'!$F:$F),"") -> 0 | P32: =IFERROR(SUMIF('NOV25'!$E:$E,CONCENTRADO!$C32,'NOV25'!$F:$F),"") -> 210000 | Q32: =IFERROR(SUMIF('DIC25'!$E:$E,CONCENTRADO!$C32,'DIC25'!$K:$K),"") -> 0 | R32: =SUM(K32:Q32) -> 210000 | S32: =$E32-$R32 -> -210000
C33: MDE2025-003L | D33: AMEX varios | F33: =IFERROR(SUMIF('ENE25'!E:E,CONCENTRADO!$C33,'ENE25'!F:F),"") -> 0 | G33: =IFERROR(SUMIF('FEB25'!$E:$E,CONCENTRADO!$C33,'FEB25'!$F:$F),"") -> 0 | H33: =IFERROR(SUMIF('MAR25'!$E:$E,CONCENTRADO!$C33,'MAR25'!$F:$F),"") -> 44555.01 | I33: =IFERROR(SUMIF('ABR25'!$E:$E,CONCENTRADO!$C33,'ABR25'!$F:$F),"") -> 11172.34 | J33: =IFERROR(SUMIF('MAY25'!$E:$E,CONCENTRADO!$C33,'MAY25'!$F:$F),"") -> 21934.28 | K33: =IFERROR(SUMIF('JUN25'!$E:$E,CONCENTRADO!$C33,'JUN25'!$F:$F),"") -> 0 | L33: =IFERROR(SUMIF('JUL25'!$E:$E,CONCENTRADO!$C33,'JUL25'!$F:$F),"") -> 23275.4 | M33: =IFERROR(SUMIF('AGO25'!$E:$E,CONCENTRADO!$C33,'AGO25'!$F:$F),"") -> 63777.87 | N33: =IFERROR(SUMIF('SEP25'!$E:$E,CONCENTRADO!$C33,'SEP25'!$F:$F),"") -> 8923.9 | O33: =IFERROR(SUMIF('OCT25'!$E:$E,CONCENTRADO!$C33,'OCT25'!$F:$F),"") -> 29832.01 | P33: =IFERROR(SUMIF('NOV25'!$E:$E,CONCENTRADO!$C33,'NOV25'!$F:$F),"") -> 0 | Q33: =IFERROR(SUMIF('DIC25'!$E:$E,CONCENTRADO!$C33,'DIC25'!$K:$K),"") -> 0 | R33: =SUM(K33:Q33) -> 125809.18 | S33: =$E33-$R33 -> -125809.18
F34: =IFERROR(SUMIF('ENE25'!E:E,CONCENTRADO!$C34,'ENE25'!F:F),"") -> 0 | G34: =IFERROR(SUMIF('FEB25'!$E:$E,CONCENTRADO!$C34,'FEB25'!$F:$F),"") -> 0 | H34: =IFERROR(SUMIF('MAR25'!$E:$E,CONCENTRADO!$C34,'MAR25'!$F:$F),"") -> 0 | I34: =IFERROR(SUMIF('ABR25'!$E:$E,CONCENTRADO!$C34,'ABR25'!$F:$F),"") -> 0 | J34: =IFERROR(SUMIF('MAY25'!$E:$E,CONCENTRADO!$C34,'MAY25'!$F:$F),"") -> 0 | K34: =IFERROR(SUMIF('JUN25'!$E:$E,CONCENTRADO!$C34,'JUN25'!$F:$F),"") -> 0 | L34: =IFERROR(SUMIF('JUL25'!$E:$E,CONCENTRADO!$C34,'JUL25'!$F:$F),"") -> 0 | M34: =IFERROR(SUMIF('AGO25'!$E:$E,CONCENTRADO!$C34,'AGO25'!$F:$F),"") -> 0 | N34: =IFERROR(SUMIF('SEP25'!$E:$E,CONCENTRADO!$C34,'SEP25'!$F:$F),"") -> 0 | O34: =IFERROR(SUMIF('OCT25'!$E:$E,CONCENTRADO!$C34,'OCT25'!$F:$F),"") -> 0 | P34: =IFERROR(SUMIF('NOV25'!$E:$E,CONCENTRADO!$C34,'NOV25'!$F:$F),"") -> 0 | Q34: =IFERROR(SUMIF('DIC25'!$E:$E,CONCENTRADO!$C34,'DIC25'!$K:$K),"") -> 0 | R34: =SUM(K34:Q34) -> 0 | S34: =$E34-$R34 -> 0
F35: =IFERROR(SUMIF('ENE25'!E:E,CONCENTRADO!$C35,'ENE25'!F:F),"") -> 0 | G35: =IFERROR(SUMIF('FEB25'!$E:$E,CONCENTRADO!$C35,'FEB25'!$F:$F),"") -> 0 | H35: =IFERROR(SUMIF('MAR25'!$E:$E,CONCENTRADO!$C35,'MAR25'!$F:$F),"") -> 0 | I35: =IFERROR(SUMIF('ABR25'!$E:$E,CONCENTRADO!$C35,'ABR25'!$F:$F),"") -> 0 | J35: =IFERROR(SUMIF('MAY25'!$E:$E,CONCENTRADO!$C35,'MAY25'!$F:$F),"") -> 0 | K35: =IFERROR(SUMIF('JUN25'!$E:$E,CONCENTRADO!$C35,'JUN25'!$F:$F),"") -> 0 | L35: =IFERROR(SUMIF('JUL25'!$E:$E,CONCENTRADO!$C35,'JUL25'!$F:$F),"") -> 0 | M35: =IFERROR(SUMIF('AGO25'!$E:$E,CONCENTRADO!$C35,'AGO25'!$F:$F),"") -> 0 | N35: =IFERROR(SUMIF('SEP25'!$E:$E,CONCENTRADO!$C35,'SEP25'!$F:$F),"") -> 0 | O35: =IFERROR(SUMIF('OCT25'!$E:$E,CONCENTRADO!$C35,'OCT25'!$F:$F),"") -> 0 | P35: =IFERROR(SUMIF('NOV25'!$E:$E,CONCENTRADO!$C35,'NOV25'!$F:$F),"") -> 0 | Q35: =IFERROR(SUMIF('DIC25'!$E:$E,CONCENTRADO!$C35,'DIC25'!$K:$K),"") -> 0 | R35: =SUM(K35:Q35) -> 0 | S35: =$E35-$R35 -> 0
F36: =IFERROR(SUMIF('ENE25'!E:E,CONCENTRADO!$C36,'ENE25'!F:F),"") -> 0 | G36: =IFERROR(SUMIF('FEB25'!$E:$E,CONCENTRADO!$C36,'FEB25'!$F:$F),"") -> 0 | H36: =IFERROR(SUMIF('MAR25'!$E:$E,CONCENTRADO!$C36,'MAR25'!$F:$F),"") -> 0 | I36: =IFERROR(SUMIF('ABR25'!$E:$E,CONCENTRADO!$C36,'ABR25'!$F:$F),"") -> 0 | J36: =IFERROR(SUMIF('MAY25'!$E:$E,CONCENTRADO!$C36,'MAY25'!$F:$F),"") -> 0 | K36: =IFERROR(SUMIF('JUN25'!$E:$E,CONCENTRADO!$C36,'JUN25'!$F:$F),"") -> 0 | L36: =IFERROR(SUMIF('JUL25'!$E:$E,CONCENTRADO!$C36,'JUL25'!$F:$F),"") -> 0 | M36: =IFERROR(SUMIF('AGO25'!$E:$E,CONCENTRADO!$C36,'AGO25'!$F:$F),"") -> 0 | N36: =IFERROR(SUMIF('SEP25'!$E:$E,CONCENTRADO!$C36,'SEP25'!$F:$F),"") -> 0 | O36: =IFERROR(SUMIF('OCT25'!$E:$E,CONCENTRADO!$C36,'OCT25'!$F:$F),"") -> 0 | P36: =IFERROR(SUMIF('NOV25'!$E:$E,CONCENTRADO!$C36,'NOV25'!$F:$F),"") -> 0 | Q36: =IFERROR(SUMIF('DIC25'!$E:$E,CONCENTRADO!$C36,'DIC25'!$K:$K),"") -> 0 | R36: =SUM(K36:Q36) -> 0 | S36: =$E36-$R36 -> 0
A37: MDE 2025-004 | B37: MATERIALES | C37: MDE2025-004 | D37: Pool de materiales | F37: =IFERROR(SUMIF('ENE25'!E:E,CONCENTRADO!$C37,'ENE25'!F:F),"") -> 192755.6 | G37: =IFERROR(SUMIF('FEB25'!$E:$E,CONCENTRADO!$C37,'FEB25'!$F:$F),"") -> 201664.38 | H37: =IFERROR(SUMIF('MAR25'!$E:$E,CONCENTRADO!$C37,'MAR25'!$F:$F),"") -> 444516.63 | I37: =IFERROR(SUMIF('ABR25'!$E:$E,CONCENTRADO!$C37,'ABR25'!$F:$F),"") -> 531090.22 | J37: =IFERROR(SUMIF('MAY25'!$E:$E,CONCENTRADO!$C37,'MAY25'!$F:$F),"") -> 550916.4 | K37: =IFERROR(SUMIF('JUN25'!$E:$E,CONCENTRADO!$C37,'JUN25'!$F:$F),"") -> 402093.47 | L37: =IFERROR(SUMIF('JUL25'!$E:$E,CONCENTRADO!$C37,'JUL25'!$F:$F),"") -> 682867.57 | M37: =IFERROR(SUMIF('AGO25'!$E:$E,CONCENTRADO!$C37,'AGO25'!$F:$F),"") -> 410964.49 | N37: =IFERROR(SUMIF('SEP25'!$E:$E,CONCENTRADO!$C37,'SEP25'!$F:$F),"") -> 572793.7 | O37: =IFERROR(SUMIF('OCT25'!$E:$E,CONCENTRADO!$C37,'OCT25'!$F:$F),"") -> 1232287.3 | P37: =IFERROR(SUMIF('NOV25'!$E:$E,CONCENTRADO!$C37,'NOV25'!$F:$F),"") -> 216526.54 | Q37: =IFERROR(SUMIF('DIC25'!$E:$E,CONCENTRADO!$C37,'DIC25'!$K:$K),"") -> 0 | R37: =SUM(K37:Q37) -> 3517533 | S37: =$E37-$R37 -> -3517533
C38: MDE2025-004A | D38: Materiales bodega | F38: =IFERROR(SUMIF('ENE25'!E:E,CONCENTRADO!$C38,'ENE25'!F:F),"") -> 223935.97 | G38: =IFERROR(SUMIF('FEB25'!$E:$E,CONCENTRADO!$C38,'FEB25'!$F:$F),"") -> 15934.35 | H38: =IFERROR(SUMIF('MAR25'!$E:$E,CONCENTRADO!$C38,'MAR25'!$F:$F),"") -> 644.03 | I38: =IFERROR(SUMIF('ABR25'!$E:$E,CONCENTRADO!$C38,'ABR25'!$F:$F),"") -> 7300 | J38: =IFERROR(SUMIF('MAY25'!$E:$E,CONCENTRADO!$C38,'MAY25'!$F:$F),"") -> 0 | K38: =IFERROR(SUMIF('JUN25'!$E:$E,CONCENTRADO!$C38,'JUN25'!$F:$F),"") -> 0 | L38: =IFERROR(SUMIF('JUL25'!$E:$E,CONCENTRADO!$C38,'JUL25'!$F:$F),"") -> 0 | M38: =IFERROR(SUMIF('AGO25'!$E:$E,CONCENTRADO!$C38,'AGO25'!$F:$F),"") -> 0 | N38: =IFERROR(SUMIF('SEP25'!$E:$E,CONCENTRADO!$C38,'SEP25'!$F:$F),"") -> 0 | O38: =IFERROR(SUMIF('OCT25'!$E:$E,CONCENTRADO!$C38,'OCT25'!$F:$F),"") -> 0 | P38: =IFERROR(SUMIF('NOV25'!$E:$E,CONCENTRADO!$C38,'NOV25'!$F:$F),"") -> 0 | Q38: =IFERROR(SUMIF('DIC25'!$E:$E,CONCENTRADO!$C38,'DIC25'!$K:$K),"") -> 0 | R38: =SUM(K38:Q38) -> 0 | S38: =$E38-$R38 -> 0
F39: =IFERROR(SUMIF('ENE25'!E:E,CONCENTRADO!$C39,'ENE25'!F:F),"") -> 0 | G39: =IFERROR(SUMIF('FEB25'!$E:$E,CONCENTRADO!$C39,'FEB25'!$F:$F),"") -> 0 | H39: =IFERROR(SUMIF('MAR25'!$E:$E,CONCENTRADO!$C39,'MAR25'!$F:$F),"") -> 0 | I39: =IFERROR(SUMIF('ABR25'!$E:$E,CONCENTRADO!$C39,'ABR25'!$F:$F),"") -> 0 | J39: =IFERROR(SUMIF('MAY25'!$E:$E,CONCENTRADO!$C39,'MAY25'!$F:$F),"") -> 0 | K39: =IFERROR(SUMIF('JUN25'!$E:$E,CONCENTRADO!$C39,'JUN25'!$F:$F),"") -> 0 | L39: =IFERROR(SUMIF('JUL25'!$E:$E,CONCENTRADO!$C39,'JUL25'!$F:$F),"") -> 0 | M39: =IFERROR(SUMIF('AGO25'!$E:$E,CONCENTRADO!$C39,'AGO25'!$F:$F),"") -> 0 | N39: =IFERROR(SUMIF('SEP25'!$E:$E,CONCENTRADO!$C39,'SEP25'!$F:$F),"") -> 0 | O39: =IFERROR(SUMIF('OCT25'!$E:$E,CONCENTRADO!$C39,'OCT25'!$F:$F),"") -> 0 | P39: =IFERROR(SUMIF('NOV25'!$E:$E,CONCENTRADO!$C39,'NOV25'!$F:$F),"") -> 0 | Q39: =IFERROR(SUMIF('DIC25'!$E:$E,CONCENTRADO!$C39,'DIC25'!$K:$K),"") -> 0 | R39: =SUM(K39:Q39) -> 0 | S39: =$E39-$R39 -> 0
A40: MDE2025-005 | C40: MDE2025-005 | D40: Fondeo para caja chica | F40: =IFERROR(SUMIF('ENE25'!E:E,CONCENTRADO!$C40,'ENE25'!F:F),"") -> 0 | G40: =IFERROR(SUMIF('FEB25'!$E:$E,CONCENTRADO!$C40,'FEB25'!$F:$F),"") -> 0 | H40: =IFERROR(SUMIF('MAR25'!$E:$E,CONCENTRADO!$C40,'MAR25'!$F:$F),"") -> 0 | I40: =IFERROR(SUMIF('ABR25'!$E:$E,CONCENTRADO!$C40,'ABR25'!$F:$F),"") -> 0 | J40: =IFERROR(SUMIF('MAY25'!$E:$E,CONCENTRADO!$C40,'MAY25'!$F:$F),"") -> 343371.88 | K40: =IFERROR(SUMIF('JUN25'!$E:$E,CONCENTRADO!$C40,'JUN25'!$F:$F),"") -> 457881.58 | L40: =IFERROR(SUMIF('JUL25'!$E:$E,CONCENTRADO!$C40,'JUL25'!$F:$F),"") -> 1472806.1 | M40: =IFERROR(SUMIF('AGO25'!$E:$E,CONCENTRADO!$C40,'AGO25'!$F:$F),"") -> 393518.17 | N40: =IFERROR(SUMIF('SEP25'!$E:$E,CONCENTRADO!$C40,'SEP25'!$F:$F),"") -> 0 | O40: =IFERROR(SUMIF('OCT25'!$E:$E,CONCENTRADO!$C40,'OCT25'!$F:$F),"") -> 0 | P40: =IFERROR(SUMIF('NOV25'!$E:$E,CONCENTRADO!$C40,'NOV25'!$F:$F),"") -> 0 | Q40: =IFERROR(SUMIF('DIC25'!$E:$E,CONCENTRADO!$C40,'DIC25'!$K:$K),"") -> 0 | R40: =SUM(K40:Q40) -> 2324205.8 | S40: =$E40-$R40 -> -2324205.8
F41: =IFERROR(SUMIF('ENE25'!E:E,CONCENTRADO!$C41,'ENE25'!F:F),"") -> 0 | G41: =IFERROR(SUMIF('FEB25'!$E:$E,CONCENTRADO!$C41,'FEB25'!$F:$F),"") -> 0 | H41: =IFERROR(SUMIF('MAR25'!$E:$E,CONCENTRADO!$C41,'MAR25'!$F:$F),"") -> 0 | I41: =IFERROR(SUMIF('ABR25'!$E:$E,CONCENTRADO!$C41,'ABR25'!$F:$F),"") -> 0 | J41: =IFERROR(SUMIF('MAY25'!$E:$E,CONCENTRADO!$C41,'MAY25'!$F:$F),"") -> 0 | K41: =IFERROR(SUMIF('JUN25'!$E:$E,CONCENTRADO!$C41,'JUN25'!$F:$F),"") -> 0 | L41: =IFERROR(SUMIF('JUL25'!$E:$E,CONCENTRADO!$C41,'JUL25'!$F:$F),"") -> 0 | M41: =IFERROR(SUMIF('AGO25'!$E:$E,CONCENTRADO!$C41,'AGO25'!$F:$F),"") -> 0 | N41: =IFERROR(SUMIF('SEP25'!$E:$E,CONCENTRADO!$C41,'SEP25'!$F:$F),"") -> 0 | O41: =IFERROR(SUMIF('OCT25'!$E:$E,CONCENTRADO!$C41,'OCT25'!$F:$F),"") -> 0 | P41: =IFERROR(SUMIF('NOV25'!$E:$E,CONCENTRADO!$C41,'NOV25'!$F:$F),"") -> 0 | Q41: =IFERROR(SUMIF('DIC25'!$E:$E,CONCENTRADO!$C41,'DIC25'!$K:$K),"") -> 0 | R41: =SUM(K41:Q41) -> 0 | S41: =$E41-$R41 -> 0
A42: MDE2025-006 | B42: LOGISTICA | C42: MDE2025-006A | D42: Servicio y mantenimiento de unidades de transporte | F42: =IFERROR(SUMIF('ENE25'!E:E,CONCENTRADO!$C42,'ENE25'!F:F),"") -> 20298.27 | G42: =IFERROR(SUMIF('FEB25'!$E:$E,CONCENTRADO!$C42,'FEB25'!$F:$F),"") -> 14880 | H42: =IFERROR(SUMIF('MAR25'!$E:$E,CONCENTRADO!$C42,'MAR25'!$F:$F),"") -> 85014 | I42: =IFERROR(SUMIF('ABR25'!$E:$E,CONCENTRADO!$C42,'ABR25'!$F:$F),"") -> 66405.55 | J42: =IFERROR(SUMIF('MAY25'!$E:$E,CONCENTRADO!$C42,'MAY25'!$F:$F),"") -> 80246.79 | K42: =IFERROR(SUMIF('JUN25'!$E:$E,CONCENTRADO!$C42,'JUN25'!$F:$F),"") -> 107430.51 | L42: =IFERROR(SUMIF('JUL25'!$E:$E,CONCENTRADO!$C42,'JUL25'!$F:$F),"") -> 85178.84 | M42: =IFERROR(SUMIF('AGO25'!$E:$E,CONCENTRADO!$C42,'AGO25'!$F:$F),"") -> 97790.03 | N42: =IFERROR(SUMIF('SEP25'!$E:$E,CONCENTRADO!$C42,'SEP25'!$F:$F),"") -> 43361.65 | O42: =IFERROR(SUMIF('OCT25'!$E:$E,CONCENTRADO!$C42,'OCT25'!$F:$F),"") -> 21876.1 | P42: =IFERROR(SUMIF('NOV25'!$E:$E,CONCENTRADO!$C42,'NOV25'!$F:$F),"") -> 12887 | Q42: =IFERROR(SUMIF('DIC25'!$E:$E,CONCENTRADO!$C42,'DIC25'!$K:$K),"") -> 0 | R42: =SUM(K42:Q42) -> 368524.13 | S42: =$E42-$R42 -> -368524.13
C43: MDE2025-006B | D43: Verificaciones y tenencias | F43: =IFERROR(SUMIF('ENE25'!E:E,CONCENTRADO!$C43,'ENE25'!F:F),"") -> 33143 | G43: =IFERROR(SUMIF('FEB25'!$E:$E,CONCENTRADO!$C43,'FEB25'!$F:$F),"") -> 1211 | H43: =IFERROR(SUMIF('MAR25'!$E:$E,CONCENTRADO!$C43,'MAR25'!$F:$F),"") -> 400 | I43: =IFERROR(SUMIF('ABR25'!$E:$E,CONCENTRADO!$C43,'ABR25'!$F:$F),"") -> 1650 | J43: =IFERROR(SUMIF('MAY25'!$E:$E,CONCENTRADO!$C43,'MAY25'!$F:$F),"") -> 2000 | K43: =IFERROR(SUMIF('JUN25'!$E:$E,CONCENTRADO!$C43,'JUN25'!$F:$F),"") -> 13034 | L43: =IFERROR(SUMIF('JUL25'!$E:$E,CONCENTRADO!$C43,'JUL25'!$F:$F),"") -> 3045 | M43: =IFERROR(SUMIF('AGO25'!$E:$E,CONCENTRADO!$C43,'AGO25'!$F:$F),"") -> 1559.15 | N43: =IFERROR(SUMIF('SEP25'!$E:$E,CONCENTRADO!$C43,'SEP25'!$F:$F),"") -> 0 | O43: =IFERROR(SUMIF('OCT25'!$E:$E,CONCENTRADO!$C43,'OCT25'!$F:$F),"") -> 0 | P43: =IFERROR(SUMIF('NOV25'!$E:$E,CONCENTRADO!$C43,'NOV25'!$F:$F),"") -> 0 | Q43: =IFERROR(SUMIF('DIC25'!$E:$E,CONCENTRADO!$C43,'DIC25'!$K:$K),"") -> 0 | R43: =SUM(K43:Q43) -> 17638.15 | S43: =$E43-$R43 -> -17638.15
C44: MDE2025-006C | D44: Gastos de transporte | F44: =IFERROR(SUMIF('ENE25'!E:E,CONCENTRADO!$C44,'ENE25'!F:F),"") -> 89234.25 | G44: =IFERROR(SUMIF('FEB25'!$E:$E,CONCENTRADO!$C44,'FEB25'!$F:$F),"") -> 900 | H44: =IFERROR(SUMIF('MAR25'!$E:$E,CONCENTRADO!$C44,'MAR25'!$F:$F),"") -> 69037.9 | I44: =IFERROR(SUMIF('ABR25'!$E:$E,CONCENTRADO!$C44,'ABR25'!$F:$F),"") -> 0 | J44: =IFERROR(SUMIF('MAY25'!$E:$E,CONCENTRADO!$C44,'MAY25'!$F:$F),"") -> 0 | K44: =IFERROR(SUMIF('JUN25'!$E:$E,CONCENTRADO!$C44,'JUN25'!$F:$F),"") -> 21747.21 | L44: =IFERROR(SUMIF('JUL25'!$E:$E,CONCENTRADO!$C44,'JUL25'!$F:$F),"") -> 0 | M44: =IFERROR(SUMIF('AGO25'!$E:$E,CONCENTRADO!$C44,'AGO25'!$F:$F),"") -> 0 | N44: =IFERROR(SUMIF('SEP25'!$E:$E,CONCENTRADO!$C44,'SEP25'!$F:$F),"") -> 0 | O44: =IFERROR(SUMIF('OCT25'!$E:$E,CONCENTRADO!$C44,'OCT25'!$F:$F),"") -> 0 | P44: =IFERROR(SUMIF('NOV25'!$E:$E,CONCENTRADO!$C44,'NOV25'!$F:$F),"") -> 0 | Q44: =IFERROR(SUMIF('DIC25'!$E:$E,CONCENTRADO!$C44,'DIC25'!$K:$K),"") -> 0 | R44: =SUM(K44:Q44) -> 21747.21 | S44: =$E44-$R44 -> -21747.21
...

Sheet CUENTAS
A1: SUBCUENTA | B1: CUENTA | C1: CLAVE | G1: FORMA DE PAGO
A2: DISEÑADORES BODEGA | B2: DISEÑOS | C2: MDE2025-001 | G2: KUSPIT SP´S
A3: SERVICIO DE RECOLECCION DE BASURA Y DESECHOS INDUSTRIALES | B3: GASTOS FIJOS | C3: MDE2025-002A | G3: SANTANDER - SUBCUENTA
A4: AGUA EMBOTELLADA | B4: GASTOS FIJOS | C4: MDE2025-002B | G4: TARJETA SANTANDER
A5: SERVICIO DE LUZ | B5: GASTOS FIJOS | C5: MDE2025-002C | G5: AMEX
A6: RENTAS | B6: GASTOS FIJOS | C6: MDE2025-002D | G6: EFECTIVO
A7: AGUA POTABLE | B7: GASTOS FIJOS | C7: MDE2025-002E | G7: BBVA
A8: SERVICIOS TELEFÓNICOS E INTERNET | B8: GASTOS FIJOS | C8: MDE2025-002F | G8: CAJA CHICA
A9: COMISIONES E INTERESES BANCARIOS | B9: GASTOS FIJOS | C9: MDE2025-002G | G9: TOKA - COMBUSTIBLES
A10: IMPUESTO PREDIAL | B10: GASTOS FIJOS | C10: MDE2025-002H | G10: TOKA - CONNECT
A11: SOCIAL MEDIA Y WEB MASTER | B11: GASTOS FIJOS | C11: MDE2025-002I | G11: SANTANDER SELECT - ENRIQUE
A12: LICENCIAS Y CERTIFICACIONES | B12: GASTOS FIJOS | C12: MDE2025-002J | G12: TOKA - TELEVIA
... A16: COMISIÓN DE NÓMINA SEMANAL | B16: GASTOS FIJOS | C16: MDE2025-002N | G16: ****
A17: NÓMINA QUINCENAL FIJA | B17: GASTOS FIJOS | C17: MDE2025-002O
A18: COMISIÓN DE NÓMINA QUINCENAL | B18: GASTOS FIJOS | C18: MDE2025-002P
A19: PRÉSTAMOS PERSONALES | B19: GASTOS FIJOS | C19: MDE2025-002Q
A20: NÓMINA EN EFECTIVO | B20: GASTOS FIJOS | C20: MDE2025-002R
A21: PAPELERÍA E INSUMOS DE LIMPIEZA | B21: GASTOS VARIOS | C21: MDE2025-003A
A22: UNIFORMES Y EPP | B22: GASTOS VARIOS | C22: MDE2025-003B
A23: TELEFONÍA E INTERNET | B23: GASTOS VARIOS | C23: MDE2025-003C
A24: COMBUSTIBLE | B24: GASTOS VARIOS | C24: MDE2025-003D
A25: FARMACIA/SALUD | B25: GASTOS VARIOS | C25: MDE2025-003F
A26: ALIMENTOS Y CONSUMOS | B26: GASTOS VARIOS | C26: MDE2025-003H
A27: HOSPEDAJE STAFF | B27: GASTOS VARIOS | C27: MDE2025-003I
A28: VUELOS STAFF | B28: GASTOS VARIOS | C28: MDE2025-003J
... A59: COMISIONES TOKA | B59: TOKA | C59: TOK2025-001C

Sheet ENE25
A1: PROVEEDOR | B1: CONCEPTO | C1: SUBCUENTA | D1: CUENTA | E1: CLAVE | F1: SUBTOTAL | G1: IVA | H1: TOTAL | I1: VALIDACIÓN | J1: FORMA DE PAGO | K1: EJECUTIVO | L1: STATUS | M1: FECHA | N1: FACTURA
A2: JOSE E ZEPEDA BURGOS | B2: REEMBOLSO COMPRA DISCO DURO / AMEX PLATINO | C2: EQUIPO DE CÓMPUTO Y TELEFONÍA | D2: =IFERROR(VLOOKUP($C2,CUENTAS[],2,0),"") -> ACTIVOS FIJOS | E2: =IFERROR(VLOOKUP($C2,CUENTAS[],3,0),"") -> MDE2025-007B | F2: 1580 | G2: 0 | H2: 1580 | I2: =IFERROR(IF(F2+G2<>H2,"REVISAR","CORRECTO"),"") -> CORRECTO | J2: KUSPIT SP´S | K2: ALEXIS/LESLIE | L2: PAGADO | M2: 45659 | N2: COMPROBANTE
A3: VIDAL ESTRADA | B3: COMPRA DE MATERIAL DE PLOMERIA | C3: INSUMOS PARA MANTENIMIENTO BODEGA | D3: =IFERROR(VLOOKUP($C3,CUENTAS[],2,0),"") -> MANTENIMIENTO | E3: =IFERROR(VLOOKUP($C3,CUENTAS[],3,0),"") -> MDE2025-009A | F3: 3799.14 | G3: 607.86 | H3: 4407 | I3: =+IF(F3+G3<>H3,"REVISAR","CORRECTO") -> CORRECTO | J3: KUSPIT SP´S | K3: ALEJANDRA | L3: PAGADO | M3: 45659 | N3: FACT13287
A4: DEKOMADERA SA DE CV | B4: COMPRA DE MATERIALES QUE YA ESTAN EN CIERRES DA198638,DA199206,DA201123 ,DA199634.DA200074,DA200512,DA202792,DA203155, DA204491 | C4: MATERIALES BODEGA | D4: =IFERROR(VLOOKUP($C4,CUENTAS[],2,0),"") -> MATERIALES | E4: =IFERROR(VLOOKUP($C4,CUENTAS[],3,0),"") -> MDE2025-004A | F4: 30000 | G4: 0 | H4: 30000 | I4: =+IF(F4+G4<>H4,"REVISAR","CORRECTO") -> CORRECTO | J4: KUSPIT SP´S | K4: ALEJANDRA | L4: PAGADO | M4: 45659 | N4: DA-30551
A5: UNALANA PAY | B5: COMISIONES BANCARIOS | C5: COMISIONES E INTERESES BANCARIOS | D5: =IFERROR(VLOOKUP($C5,CUENTAS[],2,0),"") -> GASTOS FIJOS | E5: =IFERROR(VLOOKUP($C5,CUENTAS[],3,0),"") -> MDE2025-002G | F5: 1379.31 | G5: 220.69 | H5: 1600 | I5: =+IF(F5+G5<>H5,"REVISAR","CORRECTO") -> CORRECTO | J5: KUSPIT SP´S | K5: KAWIR | L5: PAGADO | M5: 45659 | N5: PENDIENTE
A6: EVODIO DE JESUS GOMEZ | B6: PAGO MANO DE OBRA TRABAJO NUEVAS OFICINAS - EVODIO DE JESUS | C6: EDIFICIOS | D6: =IFERROR(VLOOKUP($C6,CUENTAS[],2,0),"") -> ACTIVOS FIJOS | E6: =IFERROR(VLOOKUP($C6,CUENTAS[],3,0),"") -> MDE2025-007I | F6: 3500 | G6: 0 | H6: 3500 | I6: =+IF(F6+G6<>H6,"REVISAR","CORRECTO") -> CORRECTO | J6: KUSPIT SP´S | K6: CAROLINA | L6: PAGADO | M6: 45660 | N6: N/A
A7: TIRSO DE JESUS DE LA CRUZ | B7: PAGO MANO DE OBRA TRABAJO NUEVAS OFICINAS - TIRSO DE JESUS | C7: EDIFICIOS | D7: =IFERROR(VLOOKUP($C7,CUENTAS[],2,0),"") -> ACTIVOS FIJOS | E7: =IFERROR(VLOOKUP($C7,CUENTAS[],3,0),"") -> MDE2025-007I | F7: 3200 | G7: 0 | H7: 3200 | I7: =+IF(F7+G7<>H7,"REVISAR","CORRECTO") -> CORRECTO | J7: KUSPIT SP´S | K7: CAROLINA | L7: PAGADO | M7: 45660 | N7: N/A
A8: BENITO AVILA DIAZ | B8: PAGO MANO DE OBRA - OFICINAS NUEVAS | C8: EDIFICIOS | D8: =IFERROR(VLOOKUP($C8,CUENTAS[],2,0),"") -> ACTIVOS FIJOS | E8: =IFERROR(VLOOKUP($C8,CUENTAS[],3,0),"") -> MDE2025-007I | F8: 5000 | G8: 0 | H8: 5000 | I8: =+IF(F8+G8<>H8,"REVISAR","CORRECTO") -> CORRECTO | J8: KUSPIT SP´S | K8: ENRIQUE | L8: PAGADO | M8: 45660 | N8: N/A
A9: UNALANA PAY | B9: COMISIONES BANCARIOS | C9: COMISIONES E INTERESES BANCARIOS | D9: =IFERROR(VLOOKUP($C9,CUENTAS[],2,0),"") -> GASTOS FIJOS | E9: =IFERROR(VLOOKUP($C9,CUENTAS[],3,0),"") -> MDE2025-002G | F9: 120 | G9: 0 | H9: 120 | I9: =+IF(F9+G9<>H9,"REVISAR","CORRECTO") -> CORRECTO | J9: KUSPIT SP´S | K9: KAWIR | L9: PAGADO | M9: 45660 | N9: NOMINA
A10: UNALANAPAY | B10: COMISIONES BANCARIAS | C10: COMISIONES E INTERESES BANCARIOS | D10: =IFERROR(VLOOKUP($C10,CUENTAS[],2,0),"") -> GASTOS FIJOS | E10: =IFERROR(VLOOKUP($C10,CUENTAS[],3,0),"") -> MDE2025-002G | F10: 689.66 | G10: 110.34 | H10: 800 | I10: =+IF(F10+G10<>H10,"REVISAR","CORRECTO") -> CORRECTO | J10: KUSPIT SP´S | K10: KAWIR | L10: PAGADO | M10: 45664 | N10: COMISIONES
A11: LUIS ANTONIO GARDUÑO TAPIA | B11: MO - TRABAJO PORTON BODEGA | C11: MANTENIMIENTO Y REPARACIÓN VARIOS | D11: =IFERROR(VLOOKUP($C11,CUENTAS[],2,0),"") -> MANTENIMIENTO | E11: =IFERROR(VLOOKUP($C11,CUENTAS[],3,0),"") -> MDE2025-009B | F11: 700 | G11: 0 | H11: 700 | I11: =+IF(F11+G11<>H11,"REVISAR","CORRECTO") -> CORRECTO | J11: KUSPIT SP´S | K11: ENRIQUE | L11: PAGADO | M11: 45665 | N11: N/A
A12: VICTOR AARON RODRIGUEZ MIRANDA | B12: DISEÑO Y RENDER PARA STAND ALEN 6X3 MTS - CAMBIO EXPO WALMART 2025 | C12: DISEÑADORES BODEGA | D12: =IFERROR(VLOOKUP($C12,CUENTAS[],2,0),"") -> DISEÑOS | E12: =IFERROR(VLOOKUP($C12,CUENTAS[],3,0),"") -> MDE2025-001 | F12: 6900 | G12: 281.52 | H12: 7181.52 | I12: =+IF(F12+G12<>H12,"REVISAR","CORRECTO") -> CORRECTO | J12: KUSPIT SP´S | K12: LESLIE | L12: PAGADO | M12: 45665 | N12: FACT 465
A13: RICARDO MONTENEGRO | B13: AFINACION MOTOR BALEROS FRENOS ALINEACION Y BALANCEO - JEEP | C13: SERVICIO Y MANTENIMIENTO DE UNIDADES DE TRANSPORTE | D13: =IFERROR(VLOOKUP($C13,CUENTAS[],2,0),"") -> LOGÍSTICA | E13: =IFERROR(VLOOKUP($C13,CUENTAS[],3,0),"") -> MDE2025-006A | F13: 4100 | G13: 656 | H13: 4756 | I13: =+IF(F13+G13<>H13,"REVISAR","CORRECTO") -> CORRECTO | J13: KUSPIT SP´S | K13: FERNANDO | L13: PAGADO | M13: 45665 | N13: FACT61842
A14: NORMA ELENA BURGOS REYES | B14: RENTA BODEGA DICIEMBRE 2024 | C14: RENTAS | D14: =IFERROR(VLOOKUP($C14,CUENTAS[],2,0),"") -> GASTOS FIJOS | E14: =IFERROR(VLOOKUP($C14,CUENTAS[],3,0),"") -> MDE2025-002D | F14: 80000 | G14: 0 | H14: 80000 | I14: =+IF(F14+G14<>H14,"REVISAR","CORRECTO") -> CORRECTO | J14: KUSPIT SP´S | K14: NAYELI | L14: PAGADO | M14: 45665 | N14: N/A
... A36: MARIANA GONZALEZ VARA | B36: PAGO MENSUAL SOCIAL MEDIA MES DE ENERO 2025 | C36: SOCIAL MEDIA Y WEB MASTER | D36: =IFERROR(VLOOKUP($C36,CUENTAS[],2,0),"") -> GASTOS FIJOS | E36: =IFERROR(VLOOKUP($C36,CUENTAS[],3,0),"") -> MDE2025-002I | F36: 8000 | G36: 0 | H36: 8000 | I36: =+IF(F36+G36<>H36,"REVISAR","CORRECTO") -> CORRECTO | J36: KUSPIT SP´S | K36: NAYELI | L36: PAGADO | M36: 45672 | N36: N/A
A37: Toka internacional S.A.P.I. de C.V. | B37: 2372615 | C37: COMISIONES TOKA | D37: =IFERROR(VLOOKUP($C37,CUENTAS[],2,0),"") -> TOKA | E37: =IFERROR(VLOOKUP($C37,CUENTAS[],3,0),"") -> TOK2025-001C | F37: 348 | G37: 0 | H37: 348 | I37: =+IF(F37+G37<>H37,"REVISAR","CORRECTO") -> CORRECTO | J37: KUSPIT SP´S | K37: NAYELI | L37: PAGADO | M37: 45672 | N37: FACTURA
A38: UNALANAPAY | B38: COMISIONES BANCARIAS | C38: COMISIONES E INTERESES BANCARIOS | D38: =IFERROR(VLOOKUP($C38,CUENTAS[],2,0),"") -> GASTOS FIJOS | E38: =IFERROR(VLOOKUP($C38,CUENTAS[],3,0),"") -> MDE2025-002G | F38: 172.41 | G38: 27.59 | H38: 200 | I38: =+IF(F38+G38<>H38,"REVISAR","CORRECTO") -> CORRECTO | J38: KUSPIT SP´S | K38: KAWIR | L38: PAGADO | M38: 45672 | N38: COMISIONES
A39: VICTOR MANUEL RUIZ ZARATE | B39: REEMBOLSO COMPRA DE 10 TAQUETE ARPON Y TORNILLOS PARA ZAGUÁN 13/ENE/25 | C39: INSUMOS PARA MANTENIMIENTO BODEGA | D39: =IFERROR(VLOOKUP($C39,CUENTAS[],2,0),"") -> MANTENIMIENTO | E39: =IFERROR(VLOOKUP($C39,CUENTAS[],3,0),"") -> MDE2025-009A | F39: 340 | G39: 0 | H39: 340 | I39: =+IF(F39+G39<>H39,"REVISAR","CORRECTO") -> CORRECTO | J39: KUSPIT SP´S | K39: CAROLINA | L39: PAGADO | M39: 45673 | N39: COMPROBANTE
A40: SECRETARIA DE FINANZAS | B40: TENENCIA 2025 - NAVISTAR INTERNATION CHASIS CABINA MV CUMMINS ISB6.7 197/214/239/242/279/280/289HP | C40: VERIFICACIONES Y TENENCIAS | D40: =IFERROR(VLOOKUP($C40,CUENTAS[],2,0),"") -> LOGÍSTICA | E40: =IFERROR(VLOOKUP($C40,CUENTAS[],3,0),"") -> MDE2025-006B | F40: 6051 | G40: 0 | H40: 6051 | I40: =+IF(F40+G40<>H40,"REVISAR","CORRECTO") -> CORRECTO | J40: KUSPIT SP´S | K40: FERNANDO | L40: PAGADO | M40: 45674 | N40: COMPROBANTE
A41: SECRETARIA DE FINANZAS | B41: TENENCIA 2025 - FORD RANGER T/M CREW CAB XLT 2.5L 4CIL 4A TELA/PIEL | C41: VERIFICACIONES Y TENENCIAS | D41: =IFERROR(VLOOKUP($C41,CUENTAS[],2,0),"") -> LOGÍSTICA | E41: =IFERROR(VLOOKUP($C41,CUENTAS[],3,0),"") -> MDE2025-006B | F41: 917 | G41: 0 | H41: 917 | I41: =+IF(F41+G41<>H41,"REVISAR","CORRECTO") -> CORRECTO | J41: KUSPIT SP´S | K41: FERNANDO | L41: PAGADO | M41: 45674 | N41: COMPROBANTE
A42: VOCCOPO SA DE CV | B42: SERVICIO TELEFONICO ENERO 2025 | C42: TELEFONÍA E INTERNET | D42: =IFERROR(VLOOKUP($C42,CUENTAS[],2,0),"") -> GASTOS VARIOS | E42: =IFERROR(VLOOKUP($C42,CUENTAS[],3,0),"") -> MDE2025-003C | F42: 1598 | G42: 0 | H42: 1598 | I42: =+IF(F42+G42<>H42,"REVISAR","CORRECTO") -> CORRECTO | J42: KUSPIT SP´S | K42: NAYELI | L42: PAGADO | M42: 45673 | N42: N/A
A43: COVARRUBIAS LAMA YAJAIRA ALEJANDRA | B43: COMPRA DE LLANTAS PARA MUEBLES MUESTRA BOSCH Y LAVANDERIA | C43: INSUMOS PARA MANTENIMIENTO BODEGA | D43: =IFERROR(VLOOKUP($C43,CUENTAS[],2,0),"") -> MANTENIMIENTO | E43: =IFERROR(VLOOKUP($C43,CUENTAS[],3,0),"") -> MDE2025-009A | F43: 279.32 | G43: 44.69 | H43: 324.01 | I43: =+IF(F43+G43<>H43,"REVISAR","CORRECTO") -> CORRECTO | J43: KUSPIT SP´S | K43: ALEJANDRA | L43: PAGADO | M43: 45673 | N43: 64358
A44: VICTOR MANUEL RUIZ ZARATE | B44: REEMBOLSO COMPRA DE 2 PZ DE RODAJA GIRATORIA TRACTOR Y 2 PZ DE RODAJA FIJA TRACTOR DE 4" 15ENE25 | C44: INSUMOS PARA MANTENIMIENTO BODEGA | D44: =IFERROR(VLOOKUP($C44,CUENTAS[],2,0),"") -> MANTENIMIENTO | E44: =IFERROR(VLOOKUP($C44,CUENTAS[],3,0),"") -> MDE2025-009A | F44: 580 | G44: 0 | H44: 580 | I44: =+IF(F44+G44<>H44,"REVISAR","CORRECTO") -> CORRECTO | J44: KUSPIT SP´S | K44: CAROLINA | L44: PAGADO | M44: 45673 | N44: COMPROBANTE
A45: VICTOR MANUEL RUIZ ZARATE | B45: REEMBOLSO COMPRA DE XRO ROLLO MALLA 6-6-6-6 15ENE25 | C45: INSUMOS PARA MANTENIMIENTO BODEGA | D45: =IFERROR(VLOOKUP($C45,CUENTAS[],2,0),"") -> MANTENIMIENTO | E45: =IFERROR(VLOOKUP($C45,CUENTAS[],3,0),"") -> MDE2025-009A | F45: 3024.83 | G45: 483.97 | H45: 3508.8 | I45: =+IF(F45+G45<>H45,"REVISAR","CORRECTO") -> CORRECTO | J45: KUSPIT SP´S | K45: CAROLINA | L45: PAGADO | M45: 45673 | N45: FACT T360365
A46: COVARRUBIAS LAMA YAJAIRA ALEJANDRA | B46: COMPRA DE CLAVOS Y SAPO BAÑO | C46: INSUMOS PARA MANTENIMIENTO BODEGA | D46: =IFERROR(VLOOKUP($C46,CUENTAS[],2,0),"") -> MANTENIMIENTO | E46: =IFERROR(VLOOKUP($C46,CUENTAS[],3,0),"") -> MDE2025-009A | F46: 301.72 | G46: 48.28 | H46: 350 | I46: =+IF(F46+G46<>H46,"REVISAR","CORRECTO") -> CORRECTO | J46: KUSPIT SP´S | K46: ALEJANDRA | L46: PAGADO | M46: 45673 | N46: 13314
A47: JOSE E ZEPEDA BURGOS | B47: PAGO A BENITO POR REPARACIÓN DEL PORTÓN | C47: MANTENIMIENTO Y REPARACIÓN VARIOS | D47: =IFERROR(VLOOKUP($C47,CUENTAS[],2,0),"") -> MANTENIMIENTO | E47: =IFERROR(VLOOKUP($C47,CUENTAS[],3,0),"") -> MDE2025-009B | F47: 4000 | G47: 0 | H47: 4000 | I47: =+IF(F47+G47<>H47,"REVISAR","CORRECTO") -> CORRECTO | J47: KUSPIT SP´S | K47: LESLIE | L47: PAGADO | M47: 45673 | N47: N/A
A48: JOSE E ZEPEDA BURGOS | B48: ASFALTO ENTRADA BODEGA | C48: MANTENIMIENTO Y REPARACIÓN VARIOS | D48: =IFERROR(VLOOKUP($C48,CUENTAS[],2,0),"") -> MANTENIMIENTO | E48: =IFERROR(VLOOKUP($C48,CUENTAS[],3,0),"") -> MDE2025-009B | F48: 10000 | G48: 0 | H48: 10000 | I48: =+IF(F48+G48<>H48,"REVISAR","CORRECTO") -> CORRECTO | J48: KUSPIT SP´S | K48: LESLIE | L48: PAGADO | M48: 45673 | N48: N/A
A49: BENITO AVILA DIAZ | B49: PAGO DE MANO DE OBRA CONSTRUCCION DE OFICINAS | C49: EDIFICIOS | D49: =IFERROR(VLOOKUP($C49,CUENTAS[],2,0),"") -> ACTIVOS FIJOS | E49: =IFERROR(VLOOKUP($C49,CUENTAS[],3,0),"") -> MDE2025-007I | F49: 20000 | G49: 0 | H49: 20000 | I49: =+IF(F49+G49<>H49,"REVISAR","CORRECTO") -> CORRECTO | J49: KUSPIT SP´S | K49: ENRIQUE | L49: PAGADO | M49: 45673 | N49: N/A
A50: LUIS ANTONIO GARDUÑO TAPIA | B50: PAGO MANO DE OBRA - CONSTRUCCION OFICINAS | C50: EDIFICIOS | D50: =IFERROR(VLOOKUP($C50,CUENTAS[],2,0),"") -> ACTIVOS FIJOS | E50: =IFERROR(VLOOKUP($C50,CUENTAS[],3,0),"") -> MDE2025-007I | F50: 2000 | G50: 0 | H50: 2000 | I50: =+IF(F50+G50<>H50,"REVISAR","CORRECTO") -> CORRECTO | J50: KUSPIT SP´S | K50: ENRIQUE | L50: PAGADO | M50: 45673 | N50: N/A
A51: UNALANAPAY | B51: COMISIONES BANCARIAS | C51: COMISIONES E INTERESES BANCARIOS | D51: =IFERROR(VLOOKUP($C51,CUENTAS[],2,0),"") -> GASTOS FIJOS | E51: =IFERROR(VLOOKUP($C51,CUENTAS[],3,0),"") -> MDE2025-002G | F51: 1863.84 | G51: 298.22 | H51: 2162.06 | I51: =+IF(F51+G51<>H51,"REVISAR","CORRECTO") -> CORRECTO | J51: KUSPIT SP´S | K51: KAWIR | L51: PAGADO | M51: 45673 | N51: COMISIONES
A52: CINDY PINEDA VAZQUEZ | B52: SALDO 50% TAPIZADO DE SILLAS | C52: MOBILIARIO Y EQUIPO DE OFICINA | D52: =IFERROR(VLOOKUP($C52,CUENTAS[],2,0),"") -> ACTIVOS FIJOS | E52: =IFERROR(VLOOKUP($C52,CUENTAS[],3,0),"") -> MDE2025-007E | F52: 7543.1 | G52: 1206.9 | H52: 8750 | I52: =+IF(F52+G52<>H52,"REVISAR","CORRECTO") -> CORRECTO | J52: KUSPIT SP´S | K52: ANGIE | L52: PAGADO | M52: 45674 | N52: FAC PENDIENTE
A53: ANGIE PEREZ | B53: REEMBOLSO COMPRA DE TAPETE - VIGILANCIA | C53: INSUMOS PARA MANTENIMIENTO BODEGA | D53: =IFERROR(VLOOKUP($C53,CUENTAS[],2,0),"") -> MANTENIMIENTO | E53: =IFERROR(VLOOKUP($C53,CUENTAS[],3,0),"") -> MDE2025-009A | F53: 188.79 | G53: 30.21 | H53: 219 | I53: =+IF(F53+G53<>H53,"REVISAR","CORRECTO") -> CORRECTO | J53: KUSPIT SP´S | K53: ANGIE | L53: PAGADO | M53: 45674 | N53: FACT89602
A54: ANGIE PEREZ | B54: REEMBOLSO COMPRA DE MESA- VIGILANCIA | C54: INSUMOS PARA MANTENIMIENTO BODEGA | D54: =IFERROR(VLOOKUP($C54,CUENTAS[],2,0),"") -> MANTENIMIENTO | E54: =IFERROR(VLOOKUP($C54,CUENTAS[],3,0),"") -> MDE2025-009A | F54: 688.8 | G54: 110.2 | H54: 799 | I54: =+IF(F54+G54<>H54,"REVISAR","CORRECTO") -> CORRECTO | J54: KUSPIT SP´S | K54: ANGIE | L54: PAGADO | M54: 45674 | N54: FACT 3465099
A55: EVODIO DE JESUS GOMEZ | B55: PAGO MANO DE OBRA TRABAJO NUEVAS OFICINAS | C55: EDIFICIOS | D55: =IFERROR(VLOOKUP($C55,CUENTAS[],2,0),"") -> ACTIVOS FIJOS | E55: =IFERROR(VLOOKUP($C55,CUENTAS[],3,0),"") -> MDE2025-007I | F55: 3500 | G55: 0 | H55: 3500 | I55: =+IF(F55+G55<>H55,"REVISAR","CORRECTO") -> CORRECTO | J55: KUSPIT SP´S | K55: NAYELI | L55: PAGADO | M55: 45674 | N55: N/A
A56: TIRSO DE JESUS DE LA CRUZ | B56: PAGO MANO DE OBRA TRABAJO NUEVAS OFICINAS | C56: EDIFICIOS | D56: =IFERROR(VLOOKUP($C56,CUENTAS[],2,0),"") -> ACTIVOS FIJOS | E56: =IFERROR(VLOOKUP($C56,CUENTAS[],3,0),"") -> MDE2025-007I | F56: 3200 | G56: 0 | H56: 3200 | I56: =+IF(F56+G56<>H56,"REVISAR","CORRECTO") -> CORRECTO | J56: KUSPIT SP´S | K56: NAYELI | L56: PAGADO | M56: 45674 | N56: N/A
A57: ALBERTO SUÁREZ JIMENEZ | B57: MANO DE OBRA - PROYECTOS FUTUROS 2025 | C57: PROYECTOS FUTUROS | D57: =IFERROR(VLOOKUP($C57,CUENTAS[],2,0),"") -> GASTOS VARIOS | E57: =IFERROR(VLOOKUP($C57,CUENTAS[],3,0),"") -> MDE2025-003K | F57: 10000 | G57: 0 | H57: 10000 | I57: =+IF(F57+G57<>H57,"REVISAR","CORRECTO") -> CORRECTO | J57: KUSPIT SP´S | K57: ENRIQUE | L57: PAGADO | M57: 45674 | N57: N/A
A58: GUILLERMO SUÁREZ JIMENEZ | B58: MANO DE OBRA - PROYECTOS FUTUROS 2025 | C58: PROYECTOS FUTUROS | D58: =IFERROR(VLOOKUP($C58,CUENTAS[],2,0),"") -> GASTOS VARIOS | E58: =IFERROR(VLOOKUP($C58,CUENTAS[],3,0),"") -> MDE2025-003K | F58: 10000 | G58: 0 | H58: 10000 | I58: =+IF(F58+G58<>H58,"REVISAR","CORRECTO") -> CORRECTO | J58: KUSPIT SP´S | K58: ENRIQUE | L58: PAGADO | M58: 45674 | N58: N/A
... A85: RICARDO MONTENEGRO | B85: PAGO POR SUSTITUCIÓN DE BATERIA Y SISTEMA DE ARRANQUE - MALIBÚ | C85: SERVICIO Y MANTENIMIENTO DE UNIDADES DE TRANSPORTE | D85: =IFERROR(VLOOKUP($C85,CUENTAS[],2,0),"") -> LOGÍSTICA | E85: =IFERROR(VLOOKUP($C85,CUENTAS[],3,0),"") -> MDE2025-006A | F85: 3970 | G85: 635.2 | H85: 4605.2 | I85: =+IF(F85+G85<>H85,"REVISAR","CORRECTO") -> CORRECTO | J85: KUSPIT SP´S | K85: FERNANDO | L85: PAGADO | M85: 45686 | N85: PENDIENTE
A86: Operadora Concesionaria Mexiquense SA de CV | B86: Contratación servicio flotilla MADE_3933411 - Garantia | C86: PEAJE-CASETA-TAG | D86: =IFERROR(VLOOKUP($C86,CUENTAS[],2,0),"") -> LOGÍSTICA | E86: =IFERROR(VLOOKUP($C86,CUENTAS[],3,0),"") -> MDE2025-006D | F86: -25000 | G86: 0 | H86: -25000 | I86: =+IF(F86+G86<>H86,"REVISAR","CORRECTO") -> CORRECTO | J86: KUSPIT SP´S | K86: FERNANDO | L86: PAGADO | M86: 45686 | N86: PENDIENTE / DEVOLUCION | P86: $ 25,000 DEVOLUCIÓN
A87: 365 INTELIGENCIA EN SEGURIDAD PRIVADA | B87: SERVICIO DE VIGILNCIA DEL 16 AL 31 DE ENERO 2025 | C87: VIGILANCIA | D87: =IFERROR(VLOOKUP($C87,CUENTAS[],2,0),"") -> GASTOS FIJOS | E87: =IFERROR(VLOOKUP($C87,CUENTAS[],3,0),"") -> MDE2025-002K | F87: 15525 | G87: 2484 | H87: 18009 | I87: =+IF(F87+G87<>H87,"REVISAR","CORRECTO") -> CORRECTO | J87: KUSPIT SP´S | K87: PRISCILA | L87: PAGADO | M87: 45686 | N87: 486
...

Sheet FEB25
A1: PROVEEDOR | B1: CONCEPTO | C1: SUBCUENTA | D1: CUENTA | E1: CLAVE | F1: SUBTOTAL | G1: IVA | H1: TOTAL | I1: VALIDACIÓN | J1: FORMA DE PAGO | K1: EJECUTIVO | L1: STATUS | M1: FECHA | N1: FACTURA
A2: VICTOR MANUEL RUIZ ZARATE | B2: REEMBOLSO CHAVETA INOXIDABLE - BODEGA | C2: INSUMOS PARA MANTENIMIENTO BODEGA | D2: =IFERROR(VLOOKUP($C2,CUENTAS[],2,0),"") -> MANTENIMIENTO | E2: =IFERROR(VLOOKUP($C2,CUENTAS[],3,0),"") -> MDE2025-009A | F2: 12.93 | G2: 2.07 | H2: 15 | I2: =IFERROR(IF(F2+G2<>H2,"REVISAR","CORRECTO"),"") -> CORRECTO | J2: KUSPIT SP´S | K2: NAYELI | L2: PAGADO | M2: 45693 | N2: 2692
